Workbook

Sheet Master Unit Prices
A1: Statewide Unit Bid Prices (Low Bid)
A2: One row per bid item; each project adds a Unit Price / Qty block. Values are live formulas over the Bid Data sheet.
A4: Project | D4: Lockhart Municipal (October 2026) | F4: Zapata County (October 2026)
A5: Project ID | D5: NTB2614LHART00034 | F5: NTB2521ZAPAT00053
A6: CSJ | D6: =INDEX(Projects!$C:$C,MATCH(D$5,Projects!$A:$A,0)) | F6: =INDEX(Projects!$C:$C,MATCH(F$5,Projects!$A:$A,0))
A7: Bid Date | D7: =INDEX(Projects!$F:$F,MATCH(D$5,Projects!$A:$A,0)) | F7: =INDEX(Projects!$F:$F,MATCH(F$5,Projects!$A:$A,0))
A8: Region | D8: =IF(INDEX(Projects!$H:$H,MATCH(D$5,Projects!$A:$A,0))="","(not set)",INDEX(Projects!$H:$H,MATCH(D$5,Projects!$A:$A,0))) | F8: =IF(INDEX(Projects!$H:$H,MATCH(F$5,Projects!$A:$A,0))="","(not set)",INDEX(Projects!$H:$H,MATCH(F$5,Projects!$A:$A,0)))
A9: Price Age | D9: =IF(D$7="","",IF(TODAY()-D$7<=91,"Last quarter",IF(TODAY()-D$7<=183,"Last 6 months",IF(TODAY()-D$7<=365,"Last year","Older than 1 year")))) | F9: =IF(F$7="","",IF(TODAY()-F$7<=91,"Last quarter",IF(TODAY()-F$7<=183,"Last 6 months",IF(TODAY()-F$7<=365,"Last year","Older than 1 year"))))
A10: Low Bidder | D10: =INDEX(Projects!$J:$J,MATCH(D$5,Projects!$A:$A,0)) | F10: =INDEX(Projects!$J:$J,MATCH(F$5,Projects!$A:$A,0)) | I10: Average Low-Bid Unit Price (not inflation-adjusted)
A11: Item | B11: Description | C11: Unit | D11: Unit Price | E11: Qty | F11: Unit Price | G11: Qty | I11: Last Quarter | J11: Last 6 Months | K11: Last Year | L11: All Projects | M11: # Projects
A12: C-100 | B12: CONTRACTOR QUALITY CONTROL PROGRAM | C12: LS | D12: =IF(COUNTIFS('Bid Data'!$A:$A,D$5,'Bid Data'!$H:$H,$A12,'Bid Data'!$J:$J,$C12,'Bid Data'!$G:$G,"Yes")=0,"",SUMIFS('Bid Data'!$L:$L,'Bid Data'!$A:$A,D$5,'Bid Data'!$H:$H,$A12,'Bid Data'!$J:$J,$C12,'Bid Data'!$G:$G,"Yes")) | E12: =IF(COUNTIFS('Bid Data'!$A:$A,D$5,'Bid Data'!$H:$H,$A12,'Bid Data'!$J:$J,$C12,'Bid Data'!$G:$G,"Yes")=0,"",SUMIFS('Bid Data'!$K:$K,'Bid Data'!$A:$A,D$5,'Bid Data'!$H:$H,$A12,'Bid Data'!$J:$J,$C12,'Bid Data'!$G:$G,"Yes")) | F12: =IF(COUNTIFS('Bid Data'!$A:$A,F$5,'Bid Data'!$H:$H,$A12,'Bid Data'!$J:$J,$C12,'Bid Data'!$G:$G,"Yes")=0,"",SUMIFS('Bid Data'!$L:$L,'Bid Data'!$A:$A,F$5,'Bid Data'!$H:$H,$A12,'Bid Data'!$J:$J,$C12,'Bid Data'!$G:$G,"Yes")) | G12: =IF(COUNTIFS('Bid Data'!$A:$A,F$5,'Bid Data'!$H:$H,$A12,'Bid Data'!$J:$J,$C12,'Bid Data'!$G:$G,"Yes")=0,"",SUMIFS('Bid Data'!$K:$K,'Bid Data'!$A:$A,F$5,'Bid Data'!$H:$H,$A12,'Bid Data'!$J:$J,$C12,'Bid Data'!$G:$G,"Yes")) | I12: =IFERROR(AVERAGEIFS('Bid Data'!$L:$L,'Bid Data'!$H:$H,$A12,'Bid Data'!$J:$J,$C12,'Bid Data'!$G:$G,"Yes",'Bid Data'!$D:$D,">="&(TODAY()-91)),"") | J12: =IFERROR(AVERAGEIFS('Bid Data'!$L:$L,'Bid Data'!$H:$H,$A12,'Bid Data'!$J:$J,$C12,'Bid Data'!$G:$G,"Yes",'Bid Data'!$D:$D,">="&(TODAY()-183)),"") | K12: =IFERROR(AVERAGEIFS('Bid Data'!$L:$L,'Bid Data'!$H:$H,$A12,'Bid Data'!$J:$J,$C12,'Bid Data'!$G:$G,"Yes",'Bid Data'!$D:$D,">="&(TODAY()-365)),"") | L12: =IFERROR(AVERAGEIFS('Bid Data'!$L:$L,'Bid Data'!$H:$H,$A12,'Bid Data'!$J:$J,$C12,'Bid Data'!$G:$G,"Yes"),"") | M12: =COUNTIFS('Bid Data'!$H:$H,$A12,'Bid Data'!$J:$J,$C12,'Bid Data'!$G:$G,"Yes")
A13: C-102-5.1a | B13: TEMPORARY AIR AND WATER POLLUTION, SOIL EROSION, AND SILTATION CONTROL | C13: LS | D13: =IF(COUNTIFS('Bid Data'!$A:$A,D$5,'Bid Data'!$H:$H,$A13,'Bid Data'!$J:$J,$C13,'Bid Data'!$G:$G,"Yes")=0,"",SUMIFS('Bid Data'!$L:$L,'Bid Data'!$A:$A,D$5,'Bid Data'!$H:$H,$A13,'Bid Data'!$J:$J,$C13,'Bid Data'!$G:$G,"Yes")) | E13: =IF(COUNTIFS('Bid Data'!$A:$A,D$5,'Bid Data'!$H:$H,$A13,'Bid Data'!$J:$J,$C13,'Bid Data'!$G:$G,"Yes")=0,"",SUMIFS('Bid Data'!$K:$K,'Bid Data'!$A:$A,D$5,'Bid Data'!$H:$H,$A13,'Bid Data'!$J:$J,$C13,'Bid Data'!$G:$G,"Yes")) | F13: =IF(COUNTIFS('Bid Data'!$A:$A,F$5,'Bid Data'!$H:$H,$A13,'Bid Data'!$J:$J,$C13,'Bid Data'!$G:$G,"Yes")=0,"",SUMIFS('Bid Data'!$L:$L,'Bid Data'!$A:$A,F$5,'Bid Data'!$H:$H,$A13,'Bid Data'!$J:$J,$C13,'Bid Data'!$G:$G,"Yes")) | G13: =IF(COUNTIFS('Bid Data'!$A:$A,F$5,'Bid Data'!$H:$H,$A13,'Bid Data'!$J:$J,$C13,'Bid Data'!$G:$G,"Yes")=0,"",SUMIFS('Bid Data'!$K:$K,'Bid Data'!$A:$A,F$5,'Bid Data'!$H:$H,$A13,'Bid Data'!$J:$J,$C13,'Bid Data'!$G:$G,"Yes")) | I13: =IFERROR(AVERAGEIFS('Bid Data'!$L:$L,'Bid Data'!$H:$H,$A13,'Bid Data'!$J:$J,$C13,'Bid Data'!$G:$G,"Yes",'Bid Data'!$D:$D,">="&(TODAY()-91)),"") | J13: =IFERROR(AVERAGEIFS('Bid Data'!$L:$L,'Bid Data'!$H:$H,$A13,'Bid Data'!$J:$J,$C13,'Bid Data'!$G:$G,"Yes",'Bid Data'!$D:$D,">="&(TODAY()-183)),"") | K13: =IFERROR(AVERAGEIFS('Bid Data'!$L:$L,'Bid Data'!$H:$H,$A13,'Bid Data'!$J:$J,$C13,'Bid Data'!$G:$G,"Yes",'Bid Data'!$D:$D,">="&(TODAY()-365)),"") | L13: =IFERROR(AVERAGEIFS('Bid Data'!$L:$L,'Bid Data'!$H:$H,$A13,'Bid Data'!$J:$J,$C13,'Bid Data'!$G:$G,"Yes"),"") | M13: =COUNTIFS('Bid Data'!$H:$H,$A13,'Bid Data'!$J:$J,$C13,'Bid Data'!$G:$G,"Yes")
A14: C-105 | B14: CONTRACTOR MOBILIZATION (8%) | C14: LS | D14: =IF(COUNTIFS('Bid Data'!$A:$A,D$5,'Bid Data'!$H:$H,$A14,'Bid Data'!$J:$J,$C14,'Bid Data'!$G:$G,"Yes")=0,"",SUMIFS('Bid Data'!$L:$L,'Bid Data'!$A:$A,D$5,'Bid Data'!$H:$H,$A14,'Bid Data'!$J:$J,$C14,'Bid Data'!$G:$G,"Yes")) | E14: =IF(COUNTIFS('Bid Data'!$A:$A,D$5,'Bid Data'!$H:$H,$A14,'Bid Data'!$J:$J,$C14,'Bid Data'!$G:$G,"Yes")=0,"",SUMIFS('Bid Data'!$K:$K,'Bid Data'!$A:$A,D$5,'Bid Data'!$H:$H,$A14,'Bid Data'!$J:$J,$C14,'Bid Data'!$G:$G,"Yes")) | F14: =IF(COUNTIFS('Bid Data'!$A:$A,F$5,'Bid Data'!$H:$H,$A14,'Bid Data'!$J:$J,$C14,'Bid Data'!$G:$G,"Yes")=0,"",SUMIFS('Bid Data'!$L:$L,'Bid Data'!$A:$A,F$5,'Bid Data'!$H:$H,$A14,'Bid Data'!$J:$J,$C14,'Bid Data'!$G:$G,"Yes")) | G14: =IF(COUNTIFS('Bid Data'!$A:$A,F$5,'Bid Data'!$H:$H,$A14,'Bid Data'!$J:$J,$C14,'Bid Data'!$G:$G,"Yes")=0,"",SUMIFS('Bid Data'!$K:$K,'Bid Data'!$A:$A,F$5,'Bid Data'!$H:$H,$A14,'Bid Data'!$J:$J,$C14,'Bid Data'!$G:$G,"Yes")) | I14: =IFERROR(AVERAGEIFS('Bid Data'!$L:$L,'Bid Data'!$H:$H,$A14,'Bid Data'!$J:$J,$C14,'Bid Data'!$G:$G,"Yes",'Bid Data'!$D:$D,">="&(TODAY()-91)),"") | J14: =IFERROR(AVERAGEIFS('Bid Data'!$L:$L,'Bid Data'!$H:$H,$A14,'Bid Data'!$J:$J,$C14,'Bid Data'!$G:$G,"Yes",'Bid Data'!$D:$D,">="&(TODAY()-183)),"") | K14: =IFERROR(AVERAGEIFS('Bid Data'!$L:$L,'Bid Data'!$H:$H,$A14,'Bid Data'!$J:$J,$C14,'Bid Data'!$G:$G,"Yes",'Bid Data'!$D:$D,">="&(TODAY()-365)),"") | L14: =IFERROR(AVERAGEIFS('Bid Data'!$L:$L,'Bid Data'!$H:$H,$A14,'Bid Data'!$J:$J,$C14,'Bid Data'!$G:$G,"Yes"),"") | M14: =COUNTIFS('Bid Data'!$H:$H,$A14,'Bid Data'!$J:$J,$C14,'Bid Data'!$G:$G,"Yes")
A15: D-701-5.1 | B15: EXTEND EXISTING 18-INCH REINFORCED CONCRETE PIPE (RCP), COMPLETE IN PLACE, INCLUDING REMOVAL OF EXISTING | C15: LF | D15: =IF(COUNTIFS('Bid Data'!$A:$A,D$5,'Bid Data'!$H:$H,$A15,'Bid Data'!$J:$J,$C15,'Bid Data'!$G:$G,"Yes")=0,"",SUMIFS('Bid Data'!$L:$L,'Bid Data'!$A:$A,D$5,'Bid Data'!$H:$H,$A15,'Bid Data'!$J:$J,$C15,'Bid Data'!$G:$G,"Yes")) | E15: =IF(COUNTIFS('Bid Data'!$A:$A,D$5,'Bid Data'!$H:$H,$A15,'Bid Data'!$J:$J,$C15,'Bid Data'!$G:$G,"Yes")=0,"",SUMIFS('Bid Data'!$K:$K,'Bid Data'!$A:$A,D$5,'Bid Data'!$H:$H,$A15,'Bid Data'!$J:$J,$C15,'Bid Data'!$G:$G,"Yes")) | F15: =IF(COUNTIFS('Bid Data'!$A:$A,F$5,'Bid Data'!$H:$H,$A15,'Bid Data'!$J:$J,$C15,'Bid Data'!$G:$G,"Yes")=0,"",SUMIFS('Bid Data'!$L:$L,'Bid Data'!$A:$A,F$5,'Bid Data'!$H:$H,$A15,'Bid Data'!$J:$J,$C15,'Bid Data'!$G:$G,"Yes")) | G15: =IF(COUNTIFS('Bid Data'!$A:$A,F$5,'Bid Data'!$H:$H,$A15,'Bid Data'!$J:$J,$C15,'Bid Data'!$G:$G,"Yes")=0,"",SUMIFS('Bid Data'!$K:$K,'Bid Data'!$A:$A,F$5,'Bid Data'!$H:$H,$A15,'Bid Data'!$J:$J,$C15,'Bid Data'!$G:$G,"Yes")) | I15: =IFERROR(AVERAGEIFS('Bid Data'!$L:$L,'Bid Data'!$H:$H,$A15,'Bid Data'!$J:$J,$C15,'Bid Data'!$G:$G,"Yes",'Bid Data'!$D:$D,">="&(TODAY()-91)),"") | J15: =IFERROR(AVERAGEIFS('Bid Data'!$L:$L,'Bid Data'!$H:$H,$A15,'Bid Data'!$J:$J,$C15,'Bid Data'!$G:$G,"Yes",'Bid Data'!$D:$D,">="&(TODAY()-183)),"") | K15: =IFERROR(AVERAGEIFS('Bid Data'!$L:$L,'Bid Data'!$H:$H,$A15,'Bid Data'!$J:$J,$C15,'Bid Data'!$G:$G,"Yes",'Bid Data'!$D:$D,">="&(TODAY()-365)),"") | L15: =IFERROR(AVERAGEIFS('Bid Data'!$L:$L,'Bid Data'!$H:$H,$A15,'Bid Data'!$J:$J,$C15,'Bid Data'!$G:$G,"Yes"),"") | M15: =COUNTIFS('Bid Data'!$H:$H,$A15,'Bid Data'!$J:$J,$C15,'Bid Data'!$G:$G,"Yes")
A16: D-752-5.1 | B16: REPLACE EXISTING CONCRETE- REINFORCED SAFETY END TREATMENT, FOR 18- INCH RCP PIPE, COMPLETE IN PLACE, INCLUDING REMOVAL OF EXISTING | C16: EA | D16: =IF(COUNTIFS('Bid Data'!$A:$A,D$5,'Bid Data'!$H:$H,$A16,'Bid Data'!$J:$J,$C16,'Bid Data'!$G:$G,"Yes")=0,"",SUMIFS('Bid Data'!$L:$L,'Bid Data'!$A:$A,D$5,'Bid Data'!$H:$H,$A16,'Bid Data'!$J:$J,$C16,'Bid Data'!$G:$G,"Yes")) | E16: =IF(COUNTIFS('Bid Data'!$A:$A,D$5,'Bid Data'!$H:$H,$A16,'Bid Data'!$J:$J,$C16,'Bid Data'!$G:$G,"Yes")=0,"",SUMIFS('Bid Data'!$K:$K,'Bid Data'!$A:$A,D$5,'Bid Data'!$H:$H,$A16,'Bid Data'!$J:$J,$C16,'Bid Data'!$G:$G,"Yes")) | F16: =IF(COUNTIFS('Bid Data'!$A:$A,F$5,'Bid Data'!$H:$H,$A16,'Bid Data'!$J:$J,$C16,'Bid Data'!$G:$G,"Yes")=0,"",SUMIFS('Bid Data'!$L:$L,'Bid Data'!$A:$A,F$5,'Bid Data'!$H:$H,$A16,'Bid Data'!$J:$J,$C16,'Bid Data'!$G:$G,"Yes")) | G16: =IF(COUNTIFS('Bid Data'!$A:$A,F$5,'Bid Data'!$H:$H,$A16,'Bid Data'!$J:$J,$C16,'Bid Data'!$G:$G,"Yes")=0,"",SUMIFS('Bid Data'!$K:$K,'Bid Data'!$A:$A,F$5,'Bid Data'!$H:$H,$A16,'Bid Data'!$J:$J,$C16,'Bid Data'!$G:$G,"Yes")) | I16: =IFERROR(AVERAGEIFS('Bid Data'!$L:$L,'Bid Data'!$H:$H,$A16,'Bid Data'!$J:$J,$C16,'Bid Data'!$G:$G,"Yes",'Bid Data'!$D:$D,">="&(TODAY()-91)),"") | J16: =IFERROR(AVERAGEIFS('Bid Data'!$L:$L,'Bid Data'!$H:$H,$A16,'Bid Data'!$J:$J,$C16,'Bid Data'!$G:$G,"Yes",'Bid Data'!$D:$D,">="&(TODAY()-183)),"") | K16: =IFERROR(AVERAGEIFS('Bid Data'!$L:$L,'Bid Data'!$H:$H,$A16,'Bid Data'!$J:$J,$C16,'Bid Data'!$G:$G,"Yes",'Bid Data'!$D:$D,">="&(TODAY()-365)),"") | L16: =IFERROR(AVERAGEIFS('Bid Data'!$L:$L,'Bid Data'!$H:$H,$A16,'Bid Data'!$J:$J,$C16,'Bid Data'!$G:$G,"Yes"),"") | M16: =COUNTIFS('Bid Data'!$H:$H,$A16,'Bid Data'!$J:$J,$C16,'Bid Data'!$G:$G,"Yes")
A17: F-164.1 | B17: REMOVE EXISTING FENCE AND GATES | C17: LF | D17: =IF(COUNTIFS('Bid Data'!$A:$A,D$5,'Bid Data'!$H:$H,$A17,'Bid Data'!$J:$J,$C17,'Bid Data'!$G:$G,"Yes")=0,"",SUMIFS('Bid Data'!$L:$L,'Bid Data'!$A:$A,D$5,'Bid Data'!$H:$H,$A17,'Bid Data'!$J:$J,$C17,'Bid Data'!$G:$G,"Yes")) | E17: =IF(COUNTIFS('Bid Data'!$A:$A,D$5,'Bid Data'!$H:$H,$A17,'Bid Data'!$J:$J,$C17,'Bid Data'!$G:$G,"Yes")=0,"",SUMIFS('Bid Data'!$K:$K,'Bid Data'!$A:$A,D$5,'Bid Data'!$H:$H,$A17,'Bid Data'!$J:$J,$C17,'Bid Data'!$G:$G,"Yes")) | F17: =IF(COUNTIFS('Bid Data'!$A:$A,F$5,'Bid Data'!$H:$H,$A17,'Bid Data'!$J:$J,$C17,'Bid Data'!$G:$G,"Yes")=0,"",SUMIFS('Bid Data'!$L:$L,'Bid Data'!$A:$A,F$5,'Bid Data'!$H:$H,$A17,'Bid Data'!$J:$J,$C17,'Bid Data'!$G:$G,"Yes")) | G17: =IF(COUNTIFS('Bid Data'!$A:$A,F$5,'Bid Data'!$H:$H,$A17,'Bid Data'!$J:$J,$C17,'Bid Data'!$G:$G,"Yes")=0,"",SUMIFS('Bid Data'!$K:$K,'Bid Data'!$A:$A,F$5,'Bid Data'!$H:$H,$A17,'Bid Data'!$J:$J,$C17,'Bid Data'!$G:$G,"Yes")) | I17: =IFERROR(AVERAGEIFS('Bid Data'!$L:$L,'Bid Data'!$H:$H,$A17,'Bid Data'!$J:$J,$C17,'Bid Data'!$G:$G,"Yes",'Bid Data'!$D:$D,">="&(TODAY()-91)),"") | J17: =IFERROR(AVERAGEIFS('Bid Data'!$L:$L,'Bid Data'!$H:$H,$A17,'Bid Data'!$J:$J,$C17,'Bid Data'!$G:$G,"Yes",'Bid Data'!$D:$D,">="&(TODAY()-183)),"") | K17: =IFERROR(AVERAGEIFS('Bid Data'!$L:$L,'Bid Data'!$H:$H,$A17,'Bid Data'!$J:$J,$C17,'Bid Data'!$G:$G,"Yes",'Bid Data'!$D:$D,">="&(TODAY()-365)),"") | L17: =IFERROR(AVERAGEIFS('Bid Data'!$L:$L,'Bid Data'!$H:$H,$A17,'Bid Data'!$J:$J,$C17,'Bid Data'!$G:$G,"Yes"),"") | M17: =COUNTIFS('Bid Data'!$H:$H,$A17,'Bid Data'!$J:$J,$C17,'Bid Data'!$G:$G,"Yes")
A18: F-164.2 | B18: INSTALL 8 FT TALL GAME FENCING | C18: LF | D18: =IF(COUNTIFS('Bid Data'!$A:$A,D$5,'Bid Data'!$H:$H,$A18,'Bid Data'!$J:$J,$C18,'Bid Data'!$G:$G,"Yes")=0,"",SUMIFS('Bid Data'!$L:$L,'Bid Data'!$A:$A,D$5,'Bid Data'!$H:$H,$A18,'Bid Data'!$J:$J,$C18,'Bid Data'!$G:$G,"Yes")) | E18: =IF(COUNTIFS('Bid Data'!$A:$A,D$5,'Bid Data'!$H:$H,$A18,'Bid Data'!$J:$J,$C18,'Bid Data'!$G:$G,"Yes")=0,"",SUMIFS('Bid Data'!$K:$K,'Bid Data'!$A:$A,D$5,'Bid Data'!$H:$H,$A18,'Bid Data'!$J:$J,$C18,'Bid Data'!$G:$G,"Yes")) | F18: =IF(COUNTIFS('Bid Data'!$A:$A,F$5,'Bid Data'!$H:$H,$A18,'Bid Data'!$J:$J,$C18,'Bid Data'!$G:$G,"Yes")=0,"",SUMIFS('Bid Data'!$L:$L,'Bid Data'!$A:$A,F$5,'Bid Data'!$H:$H,$A18,'Bid Data'!$J:$J,$C18,'Bid Data'!$G:$G,"Yes")) | G18: =IF(COUNTIFS('Bid Data'!$A:$A,F$5,'Bid Data'!$H:$H,$A18,'Bid Data'!$J:$J,$C18,'Bid Data'!$G:$G,"Yes")=0,"",SUMIFS('Bid Data'!$K:$K,'Bid Data'!$A:$A,F$5,'Bid Data'!$H:$H,$A18,'Bid Data'!$J:$J,$C18,'Bid Data'!$G:$G,"Yes")) | I18: =IFERROR(AVERAGEIFS('Bid Data'!$L:$L,'Bid Data'!$H:$H,$A18,'Bid Data'!$J:$J,$C18,'Bid Data'!$G:$G,"Yes",'Bid Data'!$D:$D,">="&(TODAY()-91)),"") | J18: =IFERROR(AVERAGEIFS('Bid Data'!$L:$L,'Bid Data'!$H:$H,$A18,'Bid Data'!$J:$J,$C18,'Bid Data'!$G:$G,"Yes",'Bid Data'!$D:$D,">="&(TODAY()-183)),"") | K18: =IFERROR(AVERAGEIFS('Bid Data'!$L:$L,'Bid Data'!$H:$H,$A18,'Bid Data'!$J:$J,$C18,'Bid Data'!$G:$G,"Yes",'Bid Data'!$D:$D,">="&(TODAY()-365)),"") | L18: =IFERROR(AVERAGEIFS('Bid Data'!$L:$L,'Bid Data'!$H:$H,$A18,'Bid Data'!$J:$J,$C18,'Bid Data'!$G:$G,"Yes"),"") | M18: =COUNTIFS('Bid Data'!$H:$H,$A18,'Bid Data'!$J:$J,$C18,'Bid Data'!$G:$G,"Yes")
A19: F-164.3a | B19: INSTALL NEW AUTOMATED GATE AND ASSOCIATED ELECTRICAL | C19: EA | D19: =IF(COUNTIFS('Bid Data'!$A:$A,D$5,'Bid Data'!$H:$H,$A19,'Bid Data'!$J:$J,$C19,'Bid Data'!$G:$G,"Yes")=0,"",SUMIFS('Bid Data'!$L:$L,'Bid Data'!$A:$A,D$5,'Bid Data'!$H:$H,$A19,'Bid Data'!$J:$J,$C19,'Bid Data'!$G:$G,"Yes")) | E19: =IF(COUNTIFS('Bid Data'!$A:$A,D$5,'Bid Data'!$H:$H,$A19,'Bid Data'!$J:$J,$C19,'Bid Data'!$G:$G,"Yes")=0,"",SUMIFS('Bid Data'!$K:$K,'Bid Data'!$A:$A,D$5,'Bid Data'!$H:$H,$A19,'Bid Data'!$J:$J,$C19,'Bid Data'!$G:$G,"Yes")) | F19: =IF(COUNTIFS('Bid Data'!$A:$A,F$5,'Bid Data'!$H:$H,$A19,'Bid Data'!$J:$J,$C19,'Bid Data'!$G:$G,"Yes")=0,"",SUMIFS('Bid Data'!$L:$L,'Bid Data'!$A:$A,F$5,'Bid Data'!$H:$H,$A19,'Bid Data'!$J:$J,$C19,'Bid Data'!$G:$G,"Yes")) | G19: =IF(COUNTIFS('Bid Data'!$A:$A,F$5,'Bid Data'!$H:$H,$A19,'Bid Data'!$J:$J,$C19,'Bid Data'!$G:$G,"Yes")=0,"",SUMIFS('Bid Data'!$K:$K,'Bid Data'!$A:$A,F$5,'Bid Data'!$H:$H,$A19,'Bid Data'!$J:$J,$C19,'Bid Data'!$G:$G,"Yes")) | I19: =IFERROR(AVERAGEIFS('Bid Data'!$L:$L,'Bid Data'!$H:$H,$A19,'Bid Data'!$J:$J,$C19,'Bid Data'!$G:$G,"Yes",'Bid Data'!$D:$D,">="&(TODAY()-91)),"") | J19: =IFERROR(AVERAGEIFS('Bid Data'!$L:$L,'Bid Data'!$H:$H,$A19,'Bid Data'!$J:$J,$C19,'Bid Data'!$G:$G,"Yes",'Bid Data'!$D:$D,">="&(TODAY()-183)),"") | K19: =IFERROR(AVERAGEIFS('Bid Data'!$L:$L,'Bid Data'!$H:$H,$A19,'Bid Data'!$J:$J,$C19,'Bid Data'!$G:$G,"Yes",'Bid Data'!$D:$D,">="&(TODAY()-365)),"") | L19: =IFERROR(AVERAGEIFS('Bid Data'!$L:$L,'Bid Data'!$H:$H,$A19,'Bid Data'!$J:$J,$C19,'Bid Data'!$G:$G,"Yes"),"") | M19: =COUNTIFS('Bid Data'!$H:$H,$A19,'Bid Data'!$J:$J,$C19,'Bid Data'!$G:$G,"Yes")
A20: F-164.3b | B20: INSTALL 16' SWING GATE | C20: EA | D20: =IF(COUNTIFS('Bid Data'!$A:$A,D$5,'Bid Data'!$H:$H,$A20,'Bid Data'!$J:$J,$C20,'Bid Data'!$G:$G,"Yes")=0,"",SUMIFS('Bid Data'!$L:$L,'Bid Data'!$A:$A,D$5,'Bid Data'!$H:$H,$A20,'Bid Data'!$J:$J,$C20,'Bid Data'!$G:$G,"Yes")) | E20: =IF(COUNTIFS('Bid Data'!$A:$A,D$5,'Bid Data'!$H:$H,$A20,'Bid Data'!$J:$J,$C20,'Bid Data'!$G:$G,"Yes")=0,"",SUMIFS('Bid Data'!$K:$K,'Bid Data'!$A:$A,D$5,'Bid Data'!$H:$H,$A20,'Bid Data'!$J:$J,$C20,'Bid Data'!$G:$G,"Yes")) | F20: =IF(COUNTIFS('Bid Data'!$A:$A,F$5,'Bid Data'!$H:$H,$A20,'Bid Data'!$J:$J,$C20,'Bid Data'!$G:$G,"Yes")=0,"",SUMIFS('Bid Data'!$L:$L,'Bid Data'!$A:$A,F$5,'Bid Data'!$H:$H,$A20,'Bid Data'!$J:$J,$C20,'Bid Data'!$G:$G,"Yes")) | G20: =IF(COUNTIFS('Bid Data'!$A:$A,F$5,'Bid Data'!$H:$H,$A20,'Bid Data'!$J:$J,$C20,'Bid Data'!$G:$G,"Yes")=0,"",SUMIFS('Bid Data'!$K:$K,'Bid Data'!$A:$A,F$5,'Bid Data'!$H:$H,$A20,'Bid Data'!$J:$J,$C20,'Bid Data'!$G:$G,"Yes")) | I20: =IFERROR(AVERAGEIFS('Bid Data'!$L:$L,'Bid Data'!$H:$H,$A20,'Bid Data'!$J:$J,$C20,'Bid Data'!$G:$G,"Yes",'Bid Data'!$D:$D,">="&(TODAY()-91)),"") | J20: =IFERROR(AVERAGEIFS('Bid Data'!$L:$L,'Bid Data'!$H:$H,$A20,'Bid Data'!$J:$J,$C20,'Bid Data'!$G:$G,"Yes",'Bid Data'!$D:$D,">="&(TODAY()-183)),"") | K20: =IFERROR(AVERAGEIFS('Bid Data'!$L:$L,'Bid Data'!$H:$H,$A20,'Bid Data'!$J:$J,$C20,'Bid Data'!$G:$G,"Yes",'Bid Data'!$D:$D,">="&(TODAY()-365)),"") | L20: =IFERROR(AVERAGEIFS('Bid Data'!$L:$L,'Bid Data'!$H:$H,$A20,'Bid Data'!$J:$J,$C20,'Bid Data'!$G:$G,"Yes"),"") | M20: =COUNTIFS('Bid Data'!$H:$H,$A20,'Bid Data'!$J:$J,$C20,'Bid Data'!$G:$G,"Yes")
A21: F-164.3c | B21: INSTALL PEDESTRIAN GATE | C21: EA | D21: =IF(COUNTIFS('Bid Data'!$A:$A,D$5,'Bid Data'!$H:$H,$A21,'Bid Data'!$J:$J,$C21,'Bid Data'!$G:$G,"Yes")=0,"",SUMIFS('Bid Data'!$L:$L,'Bid Data'!$A:$A,D$5,'Bid Data'!$H:$H,$A21,'Bid Data'!$J:$J,$C21,'Bid Data'!$G:$G,"Yes")) | E21: =IF(COUNTIFS('Bid Data'!$A:$A,D$5,'Bid Data'!$H:$H,$A21,'Bid Data'!$J:$J,$C21,'Bid Data'!$G:$G,"Yes")=0,"",SUMIFS('Bid Data'!$K:$K,'Bid Data'!$A:$A,D$5,'Bid Data'!$H:$H,$A21,'Bid Data'!$J:$J,$C21,'Bid Data'!$G:$G,"Yes")) | F21: =IF(COUNTIFS('Bid Data'!$A:$A,F$5,'Bid Data'!$H:$H,$A21,'Bid Data'!$J:$J,$C21,'Bid Data'!$G:$G,"Yes")=0,"",SUMIFS('Bid Data'!$L:$L,'Bid Data'!$A:$A,F$5,'Bid Data'!$H:$H,$A21,'Bid Data'!$J:$J,$C21,'Bid Data'!$G:$G,"Yes")) | G21: =IF(COUNTIFS('Bid Data'!$A:$A,F$5,'Bid Data'!$H:$H,$A21,'Bid Data'!$J:$J,$C21,'Bid Data'!$G:$G,"Yes")=0,"",SUMIFS('Bid Data'!$K:$K,'Bid Data'!$A:$A,F$5,'Bid Data'!$H:$H,$A21,'Bid Data'!$J:$J,$C21,'Bid Data'!$G:$G,"Yes")) | I21: =IFERROR(AVERAGEIFS('Bid Data'!$L:$L,'Bid Data'!$H:$H,$A21,'Bid Data'!$J:$J,$C21,'Bid Data'!$G:$G,"Yes",'Bid Data'!$D:$D,">="&(TODAY()-91)),"") | J21: =IFERROR(AVERAGEIFS('Bid Data'!$L:$L,'Bid Data'!$H:$H,$A21,'Bid Data'!$J:$J,$C21,'Bid Data'!$G:$G,"Yes",'Bid Data'!$D:$D,">="&(TODAY()-183)),"") | K21: =IFERROR(AVERAGEIFS('Bid Data'!$L:$L,'Bid Data'!$H:$H,$A21,'Bid Data'!$J:$J,$C21,'Bid Data'!$G:$G,"Yes",'Bid Data'!$D:$D,">="&(TODAY()-365)),"") | L21: =IFERROR(AVERAGEIFS('Bid Data'!$L:$L,'Bid Data'!$H:$H,$A21,'Bid Data'!$J:$J,$C21,'Bid Data'!$G:$G,"Yes"),"") | M21: =COUNTIFS('Bid Data'!$H:$H,$A21,'Bid Data'!$J:$J,$C21,'Bid Data'!$G:$G,"Yes")
A22: F-164.4 | B22: INSTALL PREDATOR APRON | C22: LF | D22: =IF(COUNTIFS('Bid Data'!$A:$A,D$5,'Bid Data'!$H:$H,$A22,'Bid Data'!$J:$J,$C22,'Bid Data'!$G:$G,"Yes")=0,"",SUMIFS('Bid Data'!$L:$L,'Bid Data'!$A:$A,D$5,'Bid Data'!$H:$H,$A22,'Bid Data'!$J:$J,$C22,'Bid Data'!$G:$G,"Yes")) | E22: =IF(COUNTIFS('Bid Data'!$A:$A,D$5,'Bid Data'!$H:$H,$A22,'Bid Data'!$J:$J,$C22,'Bid Data'!$G:$G,"Yes")=0,"",SUMIFS('Bid Data'!$K:$K,'Bid Data'!$A:$A,D$5,'Bid Data'!$H:$H,$A22,'Bid Data'!$J:$J,$C22,'Bid Data'!$G:$G,"Yes")) | F22: =IF(COUNTIFS('Bid Data'!$A:$A,F$5,'Bid Data'!$H:$H,$A22,'Bid Data'!$J:$J,$C22,'Bid Data'!$G:$G,"Yes")=0,"",SUMIFS('Bid Data'!$L:$L,'Bid Data'!$A:$A,F$5,'Bid Data'!$H:$H,$A22,'Bid Data'!$J:$J,$C22,'Bid Data'!$G:$G,"Yes")) | G22: =IF(COUNTIFS('Bid Data'!$A:$A,F$5,'Bid Data'!$H:$H,$A22,'Bid Data'!$J:$J,$C22,'Bid Data'!$G:$G,"Yes")=0,"",SUMIFS('Bid Data'!$K:$K,'Bid Data'!$A:$A,F$5,'Bid Data'!$H:$H,$A22,'Bid Data'!$J:$J,$C22,'Bid Data'!$G:$G,"Yes")) | I22: =IFERROR(AVERAGEIFS('Bid Data'!$L:$L,'Bid Data'!$H:$H,$A22,'Bid Data'!$J:$J,$C22,'Bid Data'!$G:$G,"Yes",'Bid Data'!$D:$D,">="&(TODAY()-91)),"") | J22: =IFERROR(AVERAGEIFS('Bid Data'!$L:$L,'Bid Data'!$H:$H,$A22,'Bid Data'!$J:$J,$C22,'Bid Data'!$G:$G,"Yes",'Bid Data'!$D:$D,">="&(TODAY()-183)),"") | K22: =IFERROR(AVERAGEIFS('Bid Data'!$L:$L,'Bid Data'!$H:$H,$A22,'Bid Data'!$J:$J,$C22,'Bid Data'!$G:$G,"Yes",'Bid Data'!$D:$D,">="&(TODAY()-365)),"") | L22: =IFERROR(AVERAGEIFS('Bid Data'!$L:$L,'Bid Data'!$H:$H,$A22,'Bid Data'!$J:$J,$C22,'Bid Data'!$G:$G,"Yes"),"") | M22: =COUNTIFS('Bid Data'!$H:$H,$A22,'Bid Data'!$J:$J,$C22,'Bid Data'!$G:$G,"Yes")
A23: F-164.5 | B23: INSTALL WATER GAP | C23: EA | D23: =IF(COUNTIFS('Bid Data'!$A:$A,D$5,'Bid Data'!$H:$H,$A23,'Bid Data'!$J:$J,$C23,'Bid Data'!$G:$G,"Yes")=0,"",SUMIFS('Bid Data'!$L:$L,'Bid Data'!$A:$A,D$5,'Bid Data'!$H:$H,$A23,'Bid Data'!$J:$J,$C23,'Bid Data'!$G:$G,"Yes")) | E23: =IF(COUNTIFS('Bid Data'!$A:$A,D$5,'Bid Data'!$H:$H,$A23,'Bid Data'!$J:$J,$C23,'Bid Data'!$G:$G,"Yes")=0,"",SUMIFS('Bid Data'!$K:$K,'Bid Data'!$A:$A,D$5,'Bid Data'!$H:$H,$A23,'Bid Data'!$J:$J,$C23,'Bid Data'!$G:$G,"Yes")) | F23: =IF(COUNTIFS('Bid Data'!$A:$A,F$5,'Bid Data'!$H:$H,$A23,'Bid Data'!$J:$J,$C23,'Bid Data'!$G:$G,"Yes")=0,"",SUMIFS('Bid Data'!$L:$L,'Bid Data'!$A:$A,F$5,'Bid Data'!$H:$H,$A23,'Bid Data'!$J:$J,$C23,'Bid Data'!$G:$G,"Yes")) | G23: =IF(COUNTIFS('Bid Data'!$A:$A,F$5,'Bid Data'!$H:$H,$A23,'Bid Data'!$J:$J,$C23,'Bid Data'!$G:$G,"Yes")=0,"",SUMIFS('Bid Data'!$K:$K,'Bid Data'!$A:$A,F$5,'Bid Data'!$H:$H,$A23,'Bid Data'!$J:$J,$C23,'Bid Data'!$G:$G,"Yes")) | I23: =IFERROR(AVERAGEIFS('Bid Data'!$L:$L,'Bid Data'!$H:$H,$A23,'Bid Data'!$J:$J,$C23,'Bid Data'!$G:$G,"Yes",'Bid Data'!$D:$D,">="&(TODAY()-91)),"") | J23: =IFERROR(AVERAGEIFS('Bid Data'!$L:$L,'Bid Data'!$H:$H,$A23,'Bid Data'!$J:$J,$C23,'Bid Data'!$G:$G,"Yes",'Bid Data'!$D:$D,">="&(TODAY()-183)),"") | K23: =IFERROR(AVERAGEIFS('Bid Data'!$L:$L,'Bid Data'!$H:$H,$A23,'Bid Data'!$J:$J,$C23,'Bid Data'!$G:$G,"Yes",'Bid Data'!$D:$D,">="&(TODAY()-365)),"") | L23: =IFERROR(AVERAGEIFS('Bid Data'!$L:$L,'Bid Data'!$H:$H,$A23,'Bid Data'!$J:$J,$C23,'Bid Data'!$G:$G,"Yes"),"") | M23: =COUNTIFS('Bid Data'!$H:$H,$A23,'Bid Data'!$J:$J,$C23,'Bid Data'!$G:$G,"Yes")
... A50: L-125-10 | B50: INSTALL L-853 TAXIWAY REFLECTIVE MARKERS (BLUE 86-UNITS AND GREEN 53-UNITS) AS SPECIFIED ON PLANS, COMPLETE IN PLACE | C50: EA | D50: =IF(COUNTIFS('Bid Data'!$A:$A,D$5,'Bid Data'!$H:$H,$A50,'Bid Data'!$J:$J,$C50,'Bid Data'!$G:$G,"Yes")=0,"",SUMIFS('Bid Data'!$L:$L,'Bid Data'!$A:$A,D$5,'Bid Data'!$H:$H,$A50,'Bid Data'!$J:$J,$C50,'Bid Data'!$G:$G,"Yes")) | E50: =IF(COUNTIFS('Bid Data'!$A:$A,D$5,'Bid Data'!$H:$H,$A50,'Bid Data'!$J:$J,$C50,'Bid Data'!$G:$G,"Yes")=0,"",SUMIFS('Bid Data'!$K:$K,'Bid Data'!$A:$A,D$5,'Bid Data'!$H:$H,$A50,'Bid Data'!$J:$J,$C50,'Bid Data'!$G:$G,"Yes")) | F50: =IF(COUNTIFS('Bid Data'!$A:$A,F$5,'Bid Data'!$H:$H,$A50,'Bid Data'!$J:$J,$C50,'Bid Data'!$G:$G,"Yes")=0,"",SUMIFS('Bid Data'!$L:$L,'Bid Data'!$A:$A,F$5,'Bid Data'!$H:$H,$A50,'Bid Data'!$J:$J,$C50,'Bid Data'!$G:$G,"Yes")) | G50: =IF(COUNTIFS('Bid Data'!$A:$A,F$5,'Bid Data'!$H:$H,$A50,'Bid Data'!$J:$J,$C50,'Bid Data'!$G:$G,"Yes")=0,"",SUMIFS('Bid Data'!$K:$K,'Bid Data'!$A:$A,F$5,'Bid Data'!$H:$H,$A50,'Bid Data'!$J:$J,$C50,'Bid Data'!$G:$G,"Yes")) | I50: =IFERROR(AVERAGEIFS('Bid Data'!$L:$L,'Bid Data'!$H:$H,$A50,'Bid Data'!$J:$J,$C50,'Bid Data'!$G:$G,"Yes",'Bid Data'!$D:$D,">="&(TODAY()-91)),"") | J50: =IFERROR(AVERAGEIFS('Bid Data'!$L:$L,'Bid Data'!$H:$H,$A50,'Bid Data'!$J:$J,$C50,'Bid Data'!$G:$G,"Yes",'Bid Data'!$D:$D,">="&(TODAY()-183)),"") | K50: =IFERROR(AVERAGEIFS('Bid Data'!$L:$L,'Bid Data'!$H:$H,$A50,'Bid Data'!$J:$J,$C50,'Bid Data'!$G:$G,"Yes",'Bid Data'!$D:$D,">="&(TODAY()-365)),"") | L50: =IFERROR(AVERAGEIFS('Bid Data'!$L:$L,'Bid Data'!$H:$H,$A50,'Bid Data'!$J:$J,$C50,'Bid Data'!$G:$G,"Yes"),"") | M50: =COUNTIFS('Bid Data'!$H:$H,$A50,'Bid Data'!$J:$J,$C50,'Bid Data'!$G:$G,"Yes")
A51: L-125.1 | B51: REMOVE AND DISPOSE OFF SITE, EXISTING STAKE-MOUNTED RUNWAY EDGE ‘LIGHTS FIXTURES (INCLUDING ALL UNDERGROUND ‘CONDUIT, WIRING CONNECTIONS, AND BOXES), MIRLS | D51: =IF(COUNTIFS('Bid Data'!$A:$A,D$5,'Bid Data'!$H:$H,$A51,'Bid Data'!$J:$J,$C51,'Bid Data'!$G:$G,"Yes")=0,"",SUMIFS('Bid Data'!$L:$L,'Bid Data'!$A:$A,D$5,'Bid Data'!$H:$H,$A51,'Bid Data'!$J:$J,$C51,'Bid Data'!$G:$G,"Yes")) | E51: =IF(COUNTIFS('Bid Data'!$A:$A,D$5,'Bid Data'!$H:$H,$A51,'Bid Data'!$J:$J,$C51,'Bid Data'!$G:$G,"Yes")=0,"",SUMIFS('Bid Data'!$K:$K,'Bid Data'!$A:$A,D$5,'Bid Data'!$H:$H,$A51,'Bid Data'!$J:$J,$C51,'Bid Data'!$G:$G,"Yes")) | F51: =IF(COUNTIFS('Bid Data'!$A:$A,F$5,'Bid Data'!$H:$H,$A51,'Bid Data'!$J:$J,$C51,'Bid Data'!$G:$G,"Yes")=0,"",SUMIFS('Bid Data'!$L:$L,'Bid Data'!$A:$A,F$5,'Bid Data'!$H:$H,$A51,'Bid Data'!$J:$J,$C51,'Bid Data'!$G:$G,"Yes")) | G51: =IF(COUNTIFS('Bid Data'!$A:$A,F$5,'Bid Data'!$H:$H,$A51,'Bid Data'!$J:$J,$C51,'Bid Data'!$G:$G,"Yes")=0,"",SUMIFS('Bid Data'!$K:$K,'Bid Data'!$A:$A,F$5,'Bid Data'!$H:$H,$A51,'Bid Data'!$J:$J,$C51,'Bid Data'!$G:$G,"Yes")) | I51: =IFERROR(AVERAGEIFS('Bid Data'!$L:$L,'Bid Data'!$H:$H,$A51,'Bid Data'!$J:$J,$C51,'Bid Data'!$G:$G,"Yes",'Bid Data'!$D:$D,">="&(TODAY()-91)),"") | J51: =IFERROR(AVERAGEIFS('Bid Data'!$L:$L,'Bid Data'!$H:$H,$A51,'Bid Data'!$J:$J,$C51,'Bid Data'!$G:$G,"Yes",'Bid Data'!$D:$D,">="&(TODAY()-183)),"") | K51: =IFERROR(AVERAGEIFS('Bid Data'!$L:$L,'Bid Data'!$H:$H,$A51,'Bid Data'!$J:$J,$C51,'Bid Data'!$G:$G,"Yes",'Bid Data'!$D:$D,">="&(TODAY()-365)),"") | L51: =IFERROR(AVERAGEIFS('Bid Data'!$L:$L,'Bid Data'!$H:$H,$A51,'Bid Data'!$J:$J,$C51,'Bid Data'!$G:$G,"Yes"),"") | M51: =COUNTIFS('Bid Data'!$H:$H,$A51,'Bid Data'!$J:$J,$C51,'Bid Data'!$G:$G,"Yes")
A52: L-125.2 | B52: REMOVE AND DISPOSE OFF SITE, EXISTING DIRECTIONAL SIGNAGE {INCLUDING ALL UNDERGROUND CONDUIT, WIRING CONNECTIONS, BOXES, AND CONCRETE PADS) | C52: EA | D52: =IF(COUNTIFS('Bid Data'!$A:$A,D$5,'Bid Data'!$H:$H,$A52,'Bid Data'!$J:$J,$C52,'Bid Data'!$G:$G,"Yes")=0,"",SUMIFS('Bid Data'!$L:$L,'Bid Data'!$A:$A,D$5,'Bid Data'!$H:$H,$A52,'Bid Data'!$J:$J,$C52,'Bid Data'!$G:$G,"Yes")) | E52: =IF(COUNTIFS('Bid Data'!$A:$A,D$5,'Bid Data'!$H:$H,$A52,'Bid Data'!$J:$J,$C52,'Bid Data'!$G:$G,"Yes")=0,"",SUMIFS('Bid Data'!$K:$K,'Bid Data'!$A:$A,D$5,'Bid Data'!$H:$H,$A52,'Bid Data'!$J:$J,$C52,'Bid Data'!$G:$G,"Yes")) | F52: =IF(COUNTIFS('Bid Data'!$A:$A,F$5,'Bid Data'!$H:$H,$A52,'Bid Data'!$J:$J,$C52,'Bid Data'!$G:$G,"Yes")=0,"",SUMIFS('Bid Data'!$L:$L,'Bid Data'!$A:$A,F$5,'Bid Data'!$H:$H,$A52,'Bid Data'!$J:$J,$C52,'Bid Data'!$G:$G,"Yes")) | G52: =IF(COUNTIFS('Bid Data'!$A:$A,F$5,'Bid Data'!$H:$H,$A52,'Bid Data'!$J:$J,$C52,'Bid Data'!$G:$G,"Yes")=0,"",SUMIFS('Bid Data'!$K:$K,'Bid Data'!$A:$A,F$5,'Bid Data'!$H:$H,$A52,'Bid Data'!$J:$J,$C52,'Bid Data'!$G:$G,"Yes")) | I52: =IFERROR(AVERAGEIFS('Bid Data'!$L:$L,'Bid Data'!$H:$H,$A52,'Bid Data'!$J:$J,$C52,'Bid Data'!$G:$G,"Yes",'Bid Data'!$D:$D,">="&(TODAY()-91)),"") | J52: =IFERROR(AVERAGEIFS('Bid Data'!$L:$L,'Bid Data'!$H:$H,$A52,'Bid Data'!$J:$J,$C52,'Bid Data'!$G:$G,"Yes",'Bid Data'!$D:$D,">="&(TODAY()-183)),"") | K52: =IFERROR(AVERAGEIFS('Bid Data'!$L:$L,'Bid Data'!$H:$H,$A52,'Bid Data'!$J:$J,$C52,'Bid Data'!$G:$G,"Yes",'Bid Data'!$D:$D,">="&(TODAY()-365)),"") | L52: =IFERROR(AVERAGEIFS('Bid Data'!$L:$L,'Bid Data'!$H:$H,$A52,'Bid Data'!$J:$J,$C52,'Bid Data'!$G:$G,"Yes"),"") | M52: =COUNTIFS('Bid Data'!$H:$H,$A52,'Bid Data'!$J:$J,$C52,'Bid Data'!$G:$G,"Yes")
A53: MC1-1 | B53: FURNISH AND INSTALL AIRCRAFT TIE- DOWN ANCHORS, COMPLETE | C53: EA | D53: =IF(COUNTIFS('Bid Data'!$A:$A,D$5,'Bid Data'!$H:$H,$A53,'Bid Data'!$J:$J,$C53,'Bid Data'!$G:$G,"Yes")=0,"",SUMIFS('Bid Data'!$L:$L,'Bid Data'!$A:$A,D$5,'Bid Data'!$H:$H,$A53,'Bid Data'!$J:$J,$C53,'Bid Data'!$G:$G,"Yes")) | E53: =IF(COUNTIFS('Bid Data'!$A:$A,D$5,'Bid Data'!$H:$H,$A53,'Bid Data'!$J:$J,$C53,'Bid Data'!$G:$G,"Yes")=0,"",SUMIFS('Bid Data'!$K:$K,'Bid Data'!$A:$A,D$5,'Bid Data'!$H:$H,$A53,'Bid Data'!$J:$J,$C53,'Bid Data'!$G:$G,"Yes")) | F53: =IF(COUNTIFS('Bid Data'!$A:$A,F$5,'Bid Data'!$H:$H,$A53,'Bid Data'!$J:$J,$C53,'Bid Data'!$G:$G,"Yes")=0,"",SUMIFS('Bid Data'!$L:$L,'Bid Data'!$A:$A,F$5,'Bid Data'!$H:$H,$A53,'Bid Data'!$J:$J,$C53,'Bid Data'!$G:$G,"Yes")) | G53: =IF(COUNTIFS('Bid Data'!$A:$A,F$5,'Bid Data'!$H:$H,$A53,'Bid Data'!$J:$J,$C53,'Bid Data'!$G:$G,"Yes")=0,"",SUMIFS('Bid Data'!$K:$K,'Bid Data'!$A:$A,F$5,'Bid Data'!$H:$H,$A53,'Bid Data'!$J:$J,$C53,'Bid Data'!$G:$G,"Yes")) | I53: =IFERROR(AVERAGEIFS('Bid Data'!$L:$L,'Bid Data'!$H:$H,$A53,'Bid Data'!$J:$J,$C53,'Bid Data'!$G:$G,"Yes",'Bid Data'!$D:$D,">="&(TODAY()-91)),"") | J53: =IFERROR(AVERAGEIFS('Bid Data'!$L:$L,'Bid Data'!$H:$H,$A53,'Bid Data'!$J:$J,$C53,'Bid Data'!$G:$G,"Yes",'Bid Data'!$D:$D,">="&(TODAY()-183)),"") | K53: =IFERROR(AVERAGEIFS('Bid Data'!$L:$L,'Bid Data'!$H:$H,$A53,'Bid Data'!$J:$J,$C53,'Bid Data'!$G:$G,"Yes",'Bid Data'!$D:$D,">="&(TODAY()-365)),"") | L53: =IFERROR(AVERAGEIFS('Bid Data'!$L:$L,'Bid Data'!$H:$H,$A53,'Bid Data'!$J:$J,$C53,'Bid Data'!$G:$G,"Yes"),"") | M53: =COUNTIFS('Bid Data'!$H:$H,$A53,'Bid Data'!$J:$J,$C53,'Bid Data'!$G:$G,"Yes")
A54: P-101-5.1 | B54: PAVEMENT REMOVAL AND STOCKPILE | C54: SY | D54: =IF(COUNTIFS('Bid Data'!$A:$A,D$5,'Bid Data'!$H:$H,$A54,'Bid Data'!$J:$J,$C54,'Bid Data'!$G:$G,"Yes")=0,"",SUMIFS('Bid Data'!$L:$L,'Bid Data'!$A:$A,D$5,'Bid Data'!$H:$H,$A54,'Bid Data'!$J:$J,$C54,'Bid Data'!$G:$G,"Yes")) | E54: =IF(COUNTIFS('Bid Data'!$A:$A,D$5,'Bid Data'!$H:$H,$A54,'Bid Data'!$J:$J,$C54,'Bid Data'!$G:$G,"Yes")=0,"",SUMIFS('Bid Data'!$K:$K,'Bid Data'!$A:$A,D$5,'Bid Data'!$H:$H,$A54,'Bid Data'!$J:$J,$C54,'Bid Data'!$G:$G,"Yes")) | F54: =IF(COUNTIFS('Bid Data'!$A:$A,F$5,'Bid Data'!$H:$H,$A54,'Bid Data'!$J:$J,$C54,'Bid Data'!$G:$G,"Yes")=0,"",SUMIFS('Bid Data'!$L:$L,'Bid Data'!$A:$A,F$5,'Bid Data'!$H:$H,$A54,'Bid Data'!$J:$J,$C54,'Bid Data'!$G:$G,"Yes")) | G54: =IF(COUNTIFS('Bid Data'!$A:$A,F$5,'Bid Data'!$H:$H,$A54,'Bid Data'!$J:$J,$C54,'Bid Data'!$G:$G,"Yes")=0,"",SUMIFS('Bid Data'!$K:$K,'Bid Data'!$A:$A,F$5,'Bid Data'!$H:$H,$A54,'Bid Data'!$J:$J,$C54,'Bid Data'!$G:$G,"Yes")) | I54: =IFERROR(AVERAGEIFS('Bid Data'!$L:$L,'Bid Data'!$H:$H,$A54,'Bid Data'!$J:$J,$C54,'Bid Data'!$G:$G,"Yes",'Bid Data'!$D:$D,">="&(TODAY()-91)),"") | J54: =IFERROR(AVERAGEIFS('Bid Data'!$L:$L,'Bid Data'!$H:$H,$A54,'Bid Data'!$J:$J,$C54,'Bid Data'!$G:$G,"Yes",'Bid Data'!$D:$D,">="&(TODAY()-183)),"") | K54: =IFERROR(AVERAGEIFS('Bid Data'!$L:$L,'Bid Data'!$H:$H,$A54,'Bid Data'!$J:$J,$C54,'Bid Data'!$G:$G,"Yes",'Bid Data'!$D:$D,">="&(TODAY()-365)),"") | L54: =IFERROR(AVERAGEIFS('Bid Data'!$L:$L,'Bid Data'!$H:$H,$A54,'Bid Data'!$J:$J,$C54,'Bid Data'!$G:$G,"Yes"),"") | M54: =COUNTIFS('Bid Data'!$H:$H,$A54,'Bid Data'!$J:$J,$C54,'Bid Data'!$G:$G,"Yes")
A55: P-140-3.1 | B55: TEMPORARY BARRICADES AND MARKING FOR PAVEMENT CLOSURE | C55: LS | D55: =IF(COUNTIFS('Bid Data'!$A:$A,D$5,'Bid Data'!$H:$H,$A55,'Bid Data'!$J:$J,$C55,'Bid Data'!$G:$G,"Yes")=0,"",SUMIFS('Bid Data'!$L:$L,'Bid Data'!$A:$A,D$5,'Bid Data'!$H:$H,$A55,'Bid Data'!$J:$J,$C55,'Bid Data'!$G:$G,"Yes")) | E55: =IF(COUNTIFS('Bid Data'!$A:$A,D$5,'Bid Data'!$H:$H,$A55,'Bid Data'!$J:$J,$C55,'Bid Data'!$G:$G,"Yes")=0,"",SUMIFS('Bid Data'!$K:$K,'Bid Data'!$A:$A,D$5,'Bid Data'!$H:$H,$A55,'Bid Data'!$J:$J,$C55,'Bid Data'!$G:$G,"Yes")) | F55: =IF(COUNTIFS('Bid Data'!$A:$A,F$5,'Bid Data'!$H:$H,$A55,'Bid Data'!$J:$J,$C55,'Bid Data'!$G:$G,"Yes")=0,"",SUMIFS('Bid Data'!$L:$L,'Bid Data'!$A:$A,F$5,'Bid Data'!$H:$H,$A55,'Bid Data'!$J:$J,$C55,'Bid Data'!$G:$G,"Yes")) | G55: =IF(COUNTIFS('Bid Data'!$A:$A,F$5,'Bid Data'!$H:$H,$A55,'Bid Data'!$J:$J,$C55,'Bid Data'!$G:$G,"Yes")=0,"",SUMIFS('Bid Data'!$K:$K,'Bid Data'!$A:$A,F$5,'Bid Data'!$H:$H,$A55,'Bid Data'!$J:$J,$C55,'Bid Data'!$G:$G,"Yes")) | I55: =IFERROR(AVERAGEIFS('Bid Data'!$L:$L,'Bid Data'!$H:$H,$A55,'Bid Data'!$J:$J,$C55,'Bid Data'!$G:$G,"Yes",'Bid Data'!$D:$D,">="&(TODAY()-91)),"") | J55: =IFERROR(AVERAGEIFS('Bid Data'!$L:$L,'Bid Data'!$H:$H,$A55,'Bid Data'!$J:$J,$C55,'Bid Data'!$G:$G,"Yes",'Bid Data'!$D:$D,">="&(TODAY()-183)),"") | K55: =IFERROR(AVERAGEIFS('Bid Data'!$L:$L,'Bid Data'!$H:$H,$A55,'Bid Data'!$J:$J,$C55,'Bid Data'!$G:$G,"Yes",'Bid Data'!$D:$D,">="&(TODAY()-365)),"") | L55: =IFERROR(AVERAGEIFS('Bid Data'!$L:$L,'Bid Data'!$H:$H,$A55,'Bid Data'!$J:$J,$C55,'Bid Data'!$G:$G,"Yes"),"") | M55: =COUNTIFS('Bid Data'!$H:$H,$A55,'Bid Data'!$J:$J,$C55,'Bid Data'!$G:$G,"Yes")
A56: P-152-4.1 | B56: DRAINAGE EXCAVATION AND TRENCHING | C56: CY | D56: =IF(COUNTIFS('Bid Data'!$A:$A,D$5,'Bid Data'!$H:$H,$A56,'Bid Data'!$J:$J,$C56,'Bid Data'!$G:$G,"Yes")=0,"",SUMIFS('Bid Data'!$L:$L,'Bid Data'!$A:$A,D$5,'Bid Data'!$H:$H,$A56,'Bid Data'!$J:$J,$C56,'Bid Data'!$G:$G,"Yes")) | E56: =IF(COUNTIFS('Bid Data'!$A:$A,D$5,'Bid Data'!$H:$H,$A56,'Bid Data'!$J:$J,$C56,'Bid Data'!$G:$G,"Yes")=0,"",SUMIFS('Bid Data'!$K:$K,'Bid Data'!$A:$A,D$5,'Bid Data'!$H:$H,$A56,'Bid Data'!$J:$J,$C56,'Bid Data'!$G:$G,"Yes")) | F56: =IF(COUNTIFS('Bid Data'!$A:$A,F$5,'Bid Data'!$H:$H,$A56,'Bid Data'!$J:$J,$C56,'Bid Data'!$G:$G,"Yes")=0,"",SUMIFS('Bid Data'!$L:$L,'Bid Data'!$A:$A,F$5,'Bid Data'!$H:$H,$A56,'Bid Data'!$J:$J,$C56,'Bid Data'!$G:$G,"Yes")) | G56: =IF(COUNTIFS('Bid Data'!$A:$A,F$5,'Bid Data'!$H:$H,$A56,'Bid Data'!$J:$J,$C56,'Bid Data'!$G:$G,"Yes")=0,"",SUMIFS('Bid Data'!$K:$K,'Bid Data'!$A:$A,F$5,'Bid Data'!$H:$H,$A56,'Bid Data'!$J:$J,$C56,'Bid Data'!$G:$G,"Yes")) | I56: =IFERROR(AVERAGEIFS('Bid Data'!$L:$L,'Bid Data'!$H:$H,$A56,'Bid Data'!$J:$J,$C56,'Bid Data'!$G:$G,"Yes",'Bid Data'!$D:$D,">="&(TODAY()-91)),"") | J56: =IFERROR(AVERAGEIFS('Bid Data'!$L:$L,'Bid Data'!$H:$H,$A56,'Bid Data'!$J:$J,$C56,'Bid Data'!$G:$G,"Yes",'Bid Data'!$D:$D,">="&(TODAY()-183)),"") | K56: =IFERROR(AVERAGEIFS('Bid Data'!$L:$L,'Bid Data'!$H:$H,$A56,'Bid Data'!$J:$J,$C56,'Bid Data'!$G:$G,"Yes",'Bid Data'!$D:$D,">="&(TODAY()-365)),"") | L56: =IFERROR(AVERAGEIFS('Bid Data'!$L:$L,'Bid Data'!$H:$H,$A56,'Bid Data'!$J:$J,$C56,'Bid Data'!$G:$G,"Yes"),"") | M56: =COUNTIFS('Bid Data'!$H:$H,$A56,'Bid Data'!$J:$J,$C56,'Bid Data'!$G:$G,"Yes")
A57: P-152-4.2 | B57: EMBANKMENT IN PLACE | C57: CY | D57: =IF(COUNTIFS('Bid Data'!$A:$A,D$5,'Bid Data'!$H:$H,$A57,'Bid Data'!$J:$J,$C57,'Bid Data'!$G:$G,"Yes")=0,"",SUMIFS('Bid Data'!$L:$L,'Bid Data'!$A:$A,D$5,'Bid Data'!$H:$H,$A57,'Bid Data'!$J:$J,$C57,'Bid Data'!$G:$G,"Yes")) | E57: =IF(COUNTIFS('Bid Data'!$A:$A,D$5,'Bid Data'!$H:$H,$A57,'Bid Data'!$J:$J,$C57,'Bid Data'!$G:$G,"Yes")=0,"",SUMIFS('Bid Data'!$K:$K,'Bid Data'!$A:$A,D$5,'Bid Data'!$H:$H,$A57,'Bid Data'!$J:$J,$C57,'Bid Data'!$G:$G,"Yes")) | F57: =IF(COUNTIFS('Bid Data'!$A:$A,F$5,'Bid Data'!$H:$H,$A57,'Bid Data'!$J:$J,$C57,'Bid Data'!$G:$G,"Yes")=0,"",SUMIFS('Bid Data'!$L:$L,'Bid Data'!$A:$A,F$5,'Bid Data'!$H:$H,$A57,'Bid Data'!$J:$J,$C57,'Bid Data'!$G:$G,"Yes")) | G57: =IF(COUNTIFS('Bid Data'!$A:$A,F$5,'Bid Data'!$H:$H,$A57,'Bid Data'!$J:$J,$C57,'Bid Data'!$G:$G,"Yes")=0,"",SUMIFS('Bid Data'!$K:$K,'Bid Data'!$A:$A,F$5,'Bid Data'!$H:$H,$A57,'Bid Data'!$J:$J,$C57,'Bid Data'!$G:$G,"Yes")) | I57: =IFERROR(AVERAGEIFS('Bid Data'!$L:$L,'Bid Data'!$H:$H,$A57,'Bid Data'!$J:$J,$C57,'Bid Data'!$G:$G,"Yes",'Bid Data'!$D:$D,">="&(TODAY()-91)),"") | J57: =IFERROR(AVERAGEIFS('Bid Data'!$L:$L,'Bid Data'!$H:$H,$A57,'Bid Data'!$J:$J,$C57,'Bid Data'!$G:$G,"Yes",'Bid Data'!$D:$D,">="&(TODAY()-183)),"") | K57: =IFERROR(AVERAGEIFS('Bid Data'!$L:$L,'Bid Data'!$H:$H,$A57,'Bid Data'!$J:$J,$C57,'Bid Data'!$G:$G,"Yes",'Bid Data'!$D:$D,">="&(TODAY()-365)),"") | L57: =IFERROR(AVERAGEIFS('Bid Data'!$L:$L,'Bid Data'!$H:$H,$A57,'Bid Data'!$J:$J,$C57,'Bid Data'!$G:$G,"Yes"),"") | M57: =COUNTIFS('Bid Data'!$H:$H,$A57,'Bid Data'!$J:$J,$C57,'Bid Data'!$G:$G,"Yes")
A58: P-152-4.4 | B58: EXCAVATION, GRADING, AND SUBGRADE PREPARATION | C58: SY | D58: =IF(COUNTIFS('Bid Data'!$A:$A,D$5,'Bid Data'!$H:$H,$A58,'Bid Data'!$J:$J,$C58,'Bid Data'!$G:$G,"Yes")=0,"",SUMIFS('Bid Data'!$L:$L,'Bid Data'!$A:$A,D$5,'Bid Data'!$H:$H,$A58,'Bid Data'!$J:$J,$C58,'Bid Data'!$G:$G,"Yes")) | E58: =IF(COUNTIFS('Bid Data'!$A:$A,D$5,'Bid Data'!$H:$H,$A58,'Bid Data'!$J:$J,$C58,'Bid Data'!$G:$G,"Yes")=0,"",SUMIFS('Bid Data'!$K:$K,'Bid Data'!$A:$A,D$5,'Bid Data'!$H:$H,$A58,'Bid Data'!$J:$J,$C58,'Bid Data'!$G:$G,"Yes")) | F58: =IF(COUNTIFS('Bid Data'!$A:$A,F$5,'Bid Data'!$H:$H,$A58,'Bid Data'!$J:$J,$C58,'Bid Data'!$G:$G,"Yes")=0,"",SUMIFS('Bid Data'!$L:$L,'Bid Data'!$A:$A,F$5,'Bid Data'!$H:$H,$A58,'Bid Data'!$J:$J,$C58,'Bid Data'!$G:$G,"Yes")) | G58: =IF(COUNTIFS('Bid Data'!$A:$A,F$5,'Bid Data'!$H:$H,$A58,'Bid Data'!$J:$J,$C58,'Bid Data'!$G:$G,"Yes")=0,"",SUMIFS('Bid Data'!$K:$K,'Bid Data'!$A:$A,F$5,'Bid Data'!$H:$H,$A58,'Bid Data'!$J:$J,$C58,'Bid Data'!$G:$G,"Yes")) | I58: =IFERROR(AVERAGEIFS('Bid Data'!$L:$L,'Bid Data'!$H:$H,$A58,'Bid Data'!$J:$J,$C58,'Bid Data'!$G:$G,"Yes",'Bid Data'!$D:$D,">="&(TODAY()-91)),"") | J58: =IFERROR(AVERAGEIFS('Bid Data'!$L:$L,'Bid Data'!$H:$H,$A58,'Bid Data'!$J:$J,$C58,'Bid Data'!$G:$G,"Yes",'Bid Data'!$D:$D,">="&(TODAY()-183)),"") | K58: =IFERROR(AVERAGEIFS('Bid Data'!$L:$L,'Bid Data'!$H:$H,$A58,'Bid Data'!$J:$J,$C58,'Bid Data'!$G:$G,"Yes",'Bid Data'!$D:$D,">="&(TODAY()-365)),"") | L58: =IFERROR(AVERAGEIFS('Bid Data'!$L:$L,'Bid Data'!$H:$H,$A58,'Bid Data'!$J:$J,$C58,'Bid Data'!$G:$G,"Yes"),"") | M58: =COUNTIFS('Bid Data'!$H:$H,$A58,'Bid Data'!$J:$J,$C58,'Bid Data'!$G:$G,"Yes")
A59: P-152-4.5 | B59: GRADING IN UNPAVED AREAS | C59: SY | D59: =IF(COUNTIFS('Bid Data'!$A:$A,D$5,'Bid Data'!$H:$H,$A59,'Bid Data'!$J:$J,$C59,'Bid Data'!$G:$G,"Yes")=0,"",SUMIFS('Bid Data'!$L:$L,'Bid Data'!$A:$A,D$5,'Bid Data'!$H:$H,$A59,'Bid Data'!$J:$J,$C59,'Bid Data'!$G:$G,"Yes")) | E59: =IF(COUNTIFS('Bid Data'!$A:$A,D$5,'Bid Data'!$H:$H,$A59,'Bid Data'!$J:$J,$C59,'Bid Data'!$G:$G,"Yes")=0,"",SUMIFS('Bid Data'!$K:$K,'Bid Data'!$A:$A,D$5,'Bid Data'!$H:$H,$A59,'Bid Data'!$J:$J,$C59,'Bid Data'!$G:$G,"Yes")) | F59: =IF(COUNTIFS('Bid Data'!$A:$A,F$5,'Bid Data'!$H:$H,$A59,'Bid Data'!$J:$J,$C59,'Bid Data'!$G:$G,"Yes")=0,"",SUMIFS('Bid Data'!$L:$L,'Bid Data'!$A:$A,F$5,'Bid Data'!$H:$H,$A59,'Bid Data'!$J:$J,$C59,'Bid Data'!$G:$G,"Yes")) | G59: =IF(COUNTIFS('Bid Data'!$A:$A,F$5,'Bid Data'!$H:$H,$A59,'Bid Data'!$J:$J,$C59,'Bid Data'!$G:$G,"Yes")=0,"",SUMIFS('Bid Data'!$K:$K,'Bid Data'!$A:$A,F$5,'Bid Data'!$H:$H,$A59,'Bid Data'!$J:$J,$C59,'Bid Data'!$G:$G,"Yes")) | I59: =IFERROR(AVERAGEIFS('Bid Data'!$L:$L,'Bid Data'!$H:$H,$A59,'Bid Data'!$J:$J,$C59,'Bid Data'!$G:$G,"Yes",'Bid Data'!$D:$D,">="&(TODAY()-91)),"") | J59: =IFERROR(AVERAGEIFS('Bid Data'!$L:$L,'Bid Data'!$H:$H,$A59,'Bid Data'!$J:$J,$C59,'Bid Data'!$G:$G,"Yes",'Bid Data'!$D:$D,">="&(TODAY()-183)),"") | K59: =IFERROR(AVERAGEIFS('Bid Data'!$L:$L,'Bid Data'!$H:$H,$A59,'Bid Data'!$J:$J,$C59,'Bid Data'!$G:$G,"Yes",'Bid Data'!$D:$D,">="&(TODAY()-365)),"") | L59: =IFERROR(AVERAGEIFS('Bid Data'!$L:$L,'Bid Data'!$H:$H,$A59,'Bid Data'!$J:$J,$C59,'Bid Data'!$G:$G,"Yes"),"") | M59: =COUNTIFS('Bid Data'!$H:$H,$A59,'Bid Data'!$J:$J,$C59,'Bid Data'!$G:$G,"Yes")
A60: P-152-4.6 | B60: TOPSOIL REMOVAL AND STOCKPILE (4-5 INCHES) TO REUSE | C60: SY | D60: =IF(COUNTIFS('Bid Data'!$A:$A,D$5,'Bid Data'!$H:$H,$A60,'Bid Data'!$J:$J,$C60,'Bid Data'!$G:$G,"Yes")=0,"",SUMIFS('Bid Data'!$L:$L,'Bid Data'!$A:$A,D$5,'Bid Data'!$H:$H,$A60,'Bid Data'!$J:$J,$C60,'Bid Data'!$G:$G,"Yes")) | E60: =IF(COUNTIFS('Bid Data'!$A:$A,D$5,'Bid Data'!$H:$H,$A60,'Bid Data'!$J:$J,$C60,'Bid Data'!$G:$G,"Yes")=0,"",SUMIFS('Bid Data'!$K:$K,'Bid Data'!$A:$A,D$5,'Bid Data'!$H:$H,$A60,'Bid Data'!$J:$J,$C60,'Bid Data'!$G:$G,"Yes")) | F60: =IF(COUNTIFS('Bid Data'!$A:$A,F$5,'Bid Data'!$H:$H,$A60,'Bid Data'!$J:$J,$C60,'Bid Data'!$G:$G,"Yes")=0,"",SUMIFS('Bid Data'!$L:$L,'Bid Data'!$A:$A,F$5,'Bid Data'!$H:$H,$A60,'Bid Data'!$J:$J,$C60,'Bid Data'!$G:$G,"Yes")) | G60: =IF(COUNTIFS('Bid Data'!$A:$A,F$5,'Bid Data'!$H:$H,$A60,'Bid Data'!$J:$J,$C60,'Bid Data'!$G:$G,"Yes")=0,"",SUMIFS('Bid Data'!$K:$K,'Bid Data'!$A:$A,F$5,'Bid Data'!$H:$H,$A60,'Bid Data'!$J:$J,$C60,'Bid Data'!$G:$G,"Yes")) | I60: =IFERROR(AVERAGEIFS('Bid Data'!$L:$L,'Bid Data'!$H:$H,$A60,'Bid Data'!$J:$J,$C60,'Bid Data'!$G:$G,"Yes",'Bid Data'!$D:$D,">="&(TODAY()-91)),"") | J60: =IFERROR(AVERAGEIFS('Bid Data'!$L:$L,'Bid Data'!$H:$H,$A60,'Bid Data'!$J:$J,$C60,'Bid Data'!$G:$G,"Yes",'Bid Data'!$D:$D,">="&(TODAY()-183)),"") | K60: =IFERROR(AVERAGEIFS('Bid Data'!$L:$L,'Bid Data'!$H:$H,$A60,'Bid Data'!$J:$J,$C60,'Bid Data'!$G:$G,"Yes",'Bid Data'!$D:$D,">="&(TODAY()-365)),"") | L60: =IFERROR(AVERAGEIFS('Bid Data'!$L:$L,'Bid Data'!$H:$H,$A60,'Bid Data'!$J:$J,$C60,'Bid Data'!$G:$G,"Yes"),"") | M60: =COUNTIFS('Bid Data'!$H:$H,$A60,'Bid Data'!$J:$J,$C60,'Bid Data'!$G:$G,"Yes")
A61: P-602-5.1 | B61: EMULSIFIED ASPHALT PRIME COAT (0.3 GAL/ SY) | C61: GAL | D61: =IF(COUNTIFS('Bid Data'!$A:$A,D$5,'Bid Data'!$H:$H,$A61,'Bid Data'!$J:$J,$C61,'Bid Data'!$G:$G,"Yes")=0,"",SUMIFS('Bid Data'!$L:$L,'Bid Data'!$A:$A,D$5,'Bid Data'!$H:$H,$A61,'Bid Data'!$J:$J,$C61,'Bid Data'!$G:$G,"Yes")) | E61: =IF(COUNTIFS('Bid Data'!$A:$A,D$5,'Bid Data'!$H:$H,$A61,'Bid Data'!$J:$J,$C61,'Bid Data'!$G:$G,"Yes")=0,"",SUMIFS('Bid Data'!$K:$K,'Bid Data'!$A:$A,D$5,'Bid Data'!$H:$H,$A61,'Bid Data'!$J:$J,$C61,'Bid Data'!$G:$G,"Yes")) | F61: =IF(COUNTIFS('Bid Data'!$A:$A,F$5,'Bid Data'!$H:$H,$A61,'Bid Data'!$J:$J,$C61,'Bid Data'!$G:$G,"Yes")=0,"",SUMIFS('Bid Data'!$L:$L,'Bid Data'!$A:$A,F$5,'Bid Data'!$H:$H,$A61,'Bid Data'!$J:$J,$C61,'Bid Data'!$G:$G,"Yes")) | G61: =IF(COUNTIFS('Bid Data'!$A:$A,F$5,'Bid Data'!$H:$H,$A61,'Bid Data'!$J:$J,$C61,'Bid Data'!$G:$G,"Yes")=0,"",SUMIFS('Bid Data'!$K:$K,'Bid Data'!$A:$A,F$5,'Bid Data'!$H:$H,$A61,'Bid Data'!$J:$J,$C61,'Bid Data'!$G:$G,"Yes")) | I61: =IFERROR(AVERAGEIFS('Bid Data'!$L:$L,'Bid Data'!$H:$H,$A61,'Bid Data'!$J:$J,$C61,'Bid Data'!$G:$G,"Yes",'Bid Data'!$D:$D,">="&(TODAY()-91)),"") | J61: =IFERROR(AVERAGEIFS('Bid Data'!$L:$L,'Bid Data'!$H:$H,$A61,'Bid Data'!$J:$J,$C61,'Bid Data'!$G:$G,"Yes",'Bid Data'!$D:$D,">="&(TODAY()-183)),"") | K61: =IFERROR(AVERAGEIFS('Bid Data'!$L:$L,'Bid Data'!$H:$H,$A61,'Bid Data'!$J:$J,$C61,'Bid Data'!$G:$G,"Yes",'Bid Data'!$D:$D,">="&(TODAY()-365)),"") | L61: =IFERROR(AVERAGEIFS('Bid Data'!$L:$L,'Bid Data'!$H:$H,$A61,'Bid Data'!$J:$J,$C61,'Bid Data'!$G:$G,"Yes"),"") | M61: =COUNTIFS('Bid Data'!$H:$H,$A61,'Bid Data'!$J:$J,$C61,'Bid Data'!$G:$G,"Yes")
A62: P-603-5.1 | B62: EMULSIFIED ASPHALT TACK COAT (0.10 GAL/ SY) | C62: GAL | D62: =IF(COUNTIFS('Bid Data'!$A:$A,D$5,'Bid Data'!$H:$H,$A62,'Bid Data'!$J:$J,$C62,'Bid Data'!$G:$G,"Yes")=0,"",SUMIFS('Bid Data'!$L:$L,'Bid Data'!$A:$A,D$5,'Bid Data'!$H:$H,$A62,'Bid Data'!$J:$J,$C62,'Bid Data'!$G:$G,"Yes")) | E62: =IF(COUNTIFS('Bid Data'!$A:$A,D$5,'Bid Data'!$H:$H,$A62,'Bid Data'!$J:$J,$C62,'Bid Data'!$G:$G,"Yes")=0,"",SUMIFS('Bid Data'!$K:$K,'Bid Data'!$A:$A,D$5,'Bid Data'!$H:$H,$A62,'Bid Data'!$J:$J,$C62,'Bid Data'!$G:$G,"Yes")) | F62: =IF(COUNTIFS('Bid Data'!$A:$A,F$5,'Bid Data'!$H:$H,$A62,'Bid Data'!$J:$J,$C62,'Bid Data'!$G:$G,"Yes")=0,"",SUMIFS('Bid Data'!$L:$L,'Bid Data'!$A:$A,F$5,'Bid Data'!$H:$H,$A62,'Bid Data'!$J:$J,$C62,'Bid Data'!$G:$G,"Yes")) | G62: =IF(COUNTIFS('Bid Data'!$A:$A,F$5,'Bid Data'!$H:$H,$A62,'Bid Data'!$J:$J,$C62,'Bid Data'!$G:$G,"Yes")=0,"",SUMIFS('Bid Data'!$K:$K,'Bid Data'!$A:$A,F$5,'Bid Data'!$H:$H,$A62,'Bid Data'!$J:$J,$C62,'Bid Data'!$G:$G,"Yes")) | I62: =IFERROR(AVERAGEIFS('Bid Data'!$L:$L,'Bid Data'!$H:$H,$A62,'Bid Data'!$J:$J,$C62,'Bid Data'!$G:$G,"Yes",'Bid Data'!$D:$D,">="&(TODAY()-91)),"") | J62: =IFERROR(AVERAGEIFS('Bid Data'!$L:$L,'Bid Data'!$H:$H,$A62,'Bid Data'!$J:$J,$C62,'Bid Data'!$G:$G,"Yes",'Bid Data'!$D:$D,">="&(TODAY()-183)),"") | K62: =IFERROR(AVERAGEIFS('Bid Data'!$L:$L,'Bid Data'!$H:$H,$A62,'Bid Data'!$J:$J,$C62,'Bid Data'!$G:$G,"Yes",'Bid Data'!$D:$D,">="&(TODAY()-365)),"") | L62: =IFERROR(AVERAGEIFS('Bid Data'!$L:$L,'Bid Data'!$H:$H,$A62,'Bid Data'!$J:$J,$C62,'Bid Data'!$G:$G,"Yes"),"") | M62: =COUNTIFS('Bid Data'!$H:$H,$A62,'Bid Data'!$J:$J,$C62,'Bid Data'!$G:$G,"Yes")
A63: P-610-6.2 | B63: PREPARE, INSTALL 100- X 10- FOOT THRESHOLD CONCRETE PAD AROUND L-806 LIGHT BASES, COMPLETE IN PLACE | C63: EA | D63: =IF(COUNTIFS('Bid Data'!$A:$A,D$5,'Bid Data'!$H:$H,$A63,'Bid Data'!$J:$J,$C63,'Bid Data'!$G:$G,"Yes")=0,"",SUMIFS('Bid Data'!$L:$L,'Bid Data'!$A:$A,D$5,'Bid Data'!$H:$H,$A63,'Bid Data'!$J:$J,$C63,'Bid Data'!$G:$G,"Yes")) | E63: =IF(COUNTIFS('Bid Data'!$A:$A,D$5,'Bid Data'!$H:$H,$A63,'Bid Data'!$J:$J,$C63,'Bid Data'!$G:$G,"Yes")=0,"",SUMIFS('Bid Data'!$K:$K,'Bid Data'!$A:$A,D$5,'Bid Data'!$H:$H,$A63,'Bid Data'!$J:$J,$C63,'Bid Data'!$G:$G,"Yes")) | F63: =IF(COUNTIFS('Bid Data'!$A:$A,F$5,'Bid Data'!$H:$H,$A63,'Bid Data'!$J:$J,$C63,'Bid Data'!$G:$G,"Yes")=0,"",SUMIFS('Bid Data'!$L:$L,'Bid Data'!$A:$A,F$5,'Bid Data'!$H:$H,$A63,'Bid Data'!$J:$J,$C63,'Bid Data'!$G:$G,"Yes")) | G63: =IF(COUNTIFS('Bid Data'!$A:$A,F$5,'Bid Data'!$H:$H,$A63,'Bid Data'!$J:$J,$C63,'Bid Data'!$G:$G,"Yes")=0,"",SUMIFS('Bid Data'!$K:$K,'Bid Data'!$A:$A,F$5,'Bid Data'!$H:$H,$A63,'Bid Data'!$J:$J,$C63,'Bid Data'!$G:$G,"Yes")) | I63: =IFERROR(AVERAGEIFS('Bid Data'!$L:$L,'Bid Data'!$H:$H,$A63,'Bid Data'!$J:$J,$C63,'Bid Data'!$G:$G,"Yes",'Bid Data'!$D:$D,">="&(TODAY()-91)),"") | J63: =IFERROR(AVERAGEIFS('Bid Data'!$L:$L,'Bid Data'!$H:$H,$A63,'Bid Data'!$J:$J,$C63,'Bid Data'!$G:$G,"Yes",'Bid Data'!$D:$D,">="&(TODAY()-183)),"") | K63: =IFERROR(AVERAGEIFS('Bid Data'!$L:$L,'Bid Data'!$H:$H,$A63,'Bid Data'!$J:$J,$C63,'Bid Data'!$G:$G,"Yes",'Bid Data'!$D:$D,">="&(TODAY()-365)),"") | L63: =IFERROR(AVERAGEIFS('Bid Data'!$L:$L,'Bid Data'!$H:$H,$A63,'Bid Data'!$J:$J,$C63,'Bid Data'!$G:$G,"Yes"),"") | M63: =COUNTIFS('Bid Data'!$H:$H,$A63,'Bid Data'!$J:$J,$C63,'Bid Data'!$G:$G,"Yes")
... A72: TX-506 | B72: MISCELLANEOUS EROSION CONTROL | C72: LS | D72: =IF(COUNTIFS('Bid Data'!$A:$A,D$5,'Bid Data'!$H:$H,$A72,'Bid Data'!$J:$J,$C72,'Bid Data'!$G:$G,"Yes")=0,"",SUMIFS('Bid Data'!$L:$L,'Bid Data'!$A:$A,D$5,'Bid Data'!$H:$H,$A72,'Bid Data'!$J:$J,$C72,'Bid Data'!$G:$G,"Yes")) | E72: =IF(COUNTIFS('Bid Data'!$A:$A,D$5,'Bid Data'!$H:$H,$A72,'Bid Data'!$J:$J,$C72,'Bid Data'!$G:$G,"Yes")=0,"",SUMIFS('Bid Data'!$K:$K,'Bid Data'!$A:$A,D$5,'Bid Data'!$H:$H,$A72,'Bid Data'!$J:$J,$C72,'Bid Data'!$G:$G,"Yes")) | F72: =IF(COUNTIFS('Bid Data'!$A:$A,F$5,'Bid Data'!$H:$H,$A72,'Bid Data'!$J:$J,$C72,'Bid Data'!$G:$G,"Yes")=0,"",SUMIFS('Bid Data'!$L:$L,'Bid Data'!$A:$A,F$5,'Bid Data'!$H:$H,$A72,'Bid Data'!$J:$J,$C72,'Bid Data'!$G:$G,"Yes")) | G72: =IF(COUNTIFS('Bid Data'!$A:$A,F$5,'Bid Data'!$H:$H,$A72,'Bid Data'!$J:$J,$C72,'Bid Data'!$G:$G,"Yes")=0,"",SUMIFS('Bid Data'!$K:$K,'Bid Data'!$A:$A,F$5,'Bid Data'!$H:$H,$A72,'Bid Data'!$J:$J,$C72,'Bid Data'!$G:$G,"Yes")) | I72: =IFERROR(AVERAGEIFS('Bid Data'!$L:$L,'Bid Data'!$H:$H,$A72,'Bid Data'!$J:$J,$C72,'Bid Data'!$G:$G,"Yes",'Bid Data'!$D:$D,">="&(TODAY()-91)),"") | J72: =IFERROR(AVERAGEIFS('Bid Data'!$L:$L,'Bid Data'!$H:$H,$A72,'Bid Data'!$J:$J,$C72,'Bid Data'!$G:$G,"Yes",'Bid Data'!$D:$D,">="&(TODAY()-183)),"") | K72: =IFERROR(AVERAGEIFS('Bid Data'!$L:$L,'Bid Data'!$H:$H,$A72,'Bid Data'!$J:$J,$C72,'Bid Data'!$G:$G,"Yes",'Bid Data'!$D:$D,">="&(TODAY()-365)),"") | L72: =IFERROR(AVERAGEIFS('Bid Data'!$L:$L,'Bid Data'!$H:$H,$A72,'Bid Data'!$J:$J,$C72,'Bid Data'!$G:$G,"Yes"),"") | M72: =COUNTIFS('Bid Data'!$H:$H,$A72,'Bid Data'!$J:$J,$C72,'Bid Data'!$G:$G,"Yes")

Sheet Projects
A1: Project ID | B1: Airport | C1: CSJ | D1: Scope | E1: Description | F1: Bid Date | G1: Location | H1: Region | I1: Bidders | J1: Low Bidder | K1: Low Bid | L1: Price Age | M1: Source PDF | N1: Last Updated
A2: NTB2614LHART00034 | B2: Lockhart Municipal Airport | C2: 2614LHART | D2: Fencing | E2: WILDLIFE FENCING AND GATES | F2: 46302.542 | G2: Stassney | I2: 3 | J2: Delta Specialty Contractors LLC | K2: 686695 | L2: =IF(F2="","",IF(TODAY()-F2<=91,"Last quarter",IF(TODAY()-F2<=183,"Last 6 months",IF(TODAY()-F2<=365,"Last year","Older than 1 year")))) | M2: https://www.dot.state.tx.us/AVN/avninfo/status/construct/ntb2614lhart00034br.pdf | N2: 46314.679
A3: NTB2521ZAPAT00053 | B3: Zapata County Airport | C3: 2521ZAPAT | D3: Airfield Pavement and Electrical Improvements | E3: Zapata County Airport (APY) Airfield Pavement and Electrical Improvements | F3: 46309.542 | G3: TxDOT Stassney Campus | I3: 3 | J3: Anderson Columbia Company, Inc. | K3: 5660055 | L3: =IF(F3="","",IF(TODAY()-F3<=91,"Last quarter",IF(TODAY()-F3<=183,"Last 6 months",IF(TODAY()-F3<=365,"Last year","Older than 1 year")))) | M3: https://www.dot.state.tx.us/AVN/avninfo/status/construct/ntb2521zapat00053br1.pdf | N3: 46314.682

Sheet Bid Data
A1: Project ID | B1: Airport | C1: CSJ | D1: Bid Date | E1: Bidder | F1: Bid Rank | G1: Low Bid | H1: Item | I1: Description | J1: Unit | K1: Qty | L1: Unit Price | M1: Total | N1: Verified
A2: NTB2614LHART00034 | B2: Lockhart Municipal Airport | C2: 2614LHART | D2: 46302.542 | E2: Delta Specialty Contractors LLC | F2: 1 | G2: Yes | H2: C-105 | I2: MOBILIZATION | J2: LS | K2: 1 | L2: 14000 | M2: 14000 | N2: Yes
A3: NTB2614LHART00034 | B3: Lockhart Municipal Airport | C3: 2614LHART | D3: 46302.542 | E3: Delta Specialty Contractors LLC | F3: 1 | G3: Yes | H3: TX-100 | I3: PREPARING RIGHT OF WAY | J3: LS | K3: 1 | L3: 12500 | M3: 12500 | N3: Yes
A4: NTB2614LHART00034 | B4: Lockhart Municipal Airport | C4: 2614LHART | D4: 46302.542 | E4: Delta Specialty Contractors LLC | F4: 1 | G4: Yes | H4: F-164.1 | I4: REMOVE EXISTING FENCE AND GATES | J4: LF | K4: 18750 | L4: 1.5 | M4: 28125 | N4: Yes
A5: NTB2614LHART00034 | B5: Lockhart Municipal Airport | C5: 2614LHART | D5: 46302.542 | E5: Delta Specialty Contractors LLC | F5: 1 | G5: Yes | H5: F-164.2 | I5: INSTALL 8 FT TALL GAME FENCING | J5: LF | K5: 17730 | L5: 21 | M5: 372330 | N5: Yes
A6: NTB2614LHART00034 | B6: Lockhart Municipal Airport | C6: 2614LHART | D6: 46302.542 | E6: Delta Specialty Contractors LLC | F6: 1 | G6: Yes | H6: F-164.3a | I6: INSTALL NEW AUTOMATED GATE AND ASSOCIATED ELECTRICAL | J6: EA | K6: 1 | L6: 29500 | M6: 29500 | N6: Yes
A7: NTB2614LHART00034 | B7: Lockhart Municipal Airport | C7: 2614LHART | D7: 46302.542 | E7: Delta Specialty Contractors LLC | F7: 1 | G7: Yes | H7: F-164.3b | I7: INSTALL 16' SWING GATE | J7: EA | K7: 3 | L7: 2250 | M7: 6750 | N7: Yes
A8: NTB2614LHART00034 | B8: Lockhart Municipal Airport | C8: 2614LHART | D8: 46302.542 | E8: Delta Specialty Contractors LLC | F8: 1 | G8: Yes | H8: F-164.3c | I8: INSTALL PEDESTRIAN GATE | J8: EA | K8: 1 | L8: 1850 | M8: 1850 | N8: Yes
A9: NTB2614LHART00034 | B9: Lockhart Municipal Airport | C9: 2614LHART | D9: 46302.542 | E9: Delta Specialty Contractors LLC | F9: 1 | G9: Yes | H9: F-164.4 | I9: INSTALL PREDATOR APRON | J9: LF | K9: 17630 | L9: 3 | M9: 52890 | N9: Yes
A10: NTB2614LHART00034 | B10: Lockhart Municipal Airport | C10: 2614LHART | D10: 46302.542 | E10: Delta Specialty Contractors LLC | F10: 1 | G10: Yes | H10: F-164.5 | I10: INSTALL WATER GAP | J10: EA | K10: 3 | L10: 47500 | M10: 142500 | N10: Yes
A11: NTB2614LHART00034 | B11: Lockhart Municipal Airport | C11: 2614LHART | D11: 46302.542 | E11: Delta Specialty Contractors LLC | F11: 1 | G11: Yes | H11: L-125 | I11: INSTALL SOLAR POWERED OBSTRUCTION LIGHT, COMPLETE | J11: EA | K11: 5 | L11: 2850 | M11: 14250 | N11: Yes
A12: NTB2614LHART00034 | B12: Lockhart Municipal Airport | C12: 2614LHART | D12: 46302.542 | E12: Delta Specialty Contractors LLC | F12: 1 | G12: Yes | H12: TX-506 | I12: MISCELLANEOUS EROSION CONTROL | J12: LS | K12: 1 | L12: 12000 | M12: 12000 | N12: Yes
A13: NTB2614LHART00034 | B13: Lockhart Municipal Airport | C13: 2614LHART | D13: 46302.542 | E13: Fencing Unlimited LLC | F13: 2 | G13: No | H13: C-105 | I13: MOBILIZATION | J13: LS | K13: 1 | L13: 40000 | M13: 40000 | N13: Yes
... A74: NTB2521ZAPAT00053 | B74: Zapata County Airport | C74: 2521ZAPAT | D74: 46309.542 | E74: Anderson Columbia Company, Inc. | F74: 1 | G74: Yes | H74: L-115.2 | I74: HEAVY-DUTY ELECTRICAL BOX WITH LID, 17X30X24 INCHES, AT VAULT BUILDING | J74: EA | K74: 3 | L74: 4500 | M74: 13500 | N74: Yes
A75: NTB2521ZAPAT00053 | B75: Zapata County Airport | C75: 2521ZAPAT | D75: 46309.542 | E75: Anderson Columbia Company, Inc. | F75: 1 | G75: Yes | H75: L-125.1 | I75: REMOVE AND DISPOSE OFF SITE, EXISTING STAKE-MOUNTED RUNWAY EDGE ‘LIGHTS FIXTURES (INCLUDING ALL UNDERGROUND ‘CONDUIT, WIRING CONNECTIONS, AND BOXES), MIRLS | K75: 118 | L75: 180 | M75: 21240 | N75: Yes
A76: NTB2521ZAPAT00053 | B76: Zapata County Airport | C76: 2521ZAPAT | D76: 46309.542 | E76: Anderson Columbia Company, Inc. | F76: 1 | G76: Yes | H76: L-125.2 | I76: REMOVE AND DISPOSE OFF SITE, EXISTING DIRECTIONAL SIGNAGE {INCLUDING ALL UNDERGROUND CONDUIT, WIRING CONNECTIONS, BOXES, AND CONCRETE PADS) | J76: EA | K76: 11 | L76: 600 | M76: 6600 | N76: Yes
A77: NTB2521ZAPAT00053 | B77: Zapata County Airport | C77: 2521ZAPAT | D77: 46309.542 | E77: Anderson Columbia Company, Inc. | F77: 1 | G77: Yes | H77: L-125-3 | I77: REMOVE AND DISPOSE OFF SITE, EXISTING REILS UNITS ON RWY 12-30 END {INCLUDING ALL UNDERGROUND CONDUIT, WIRING CONNECTIONS, BOXES, AND CONCRETE FOUNDATION PADS) | J77: EA | K77: 4 | L77: 900 | M77: 3600 | N77: Yes
A78: NTB2521ZAPAT00053 | B78: Zapata County Airport | C78: 2521ZAPAT | D78: 46309.542 | E78: Anderson Columbia Company, Inc. | F78: 1 | G78: Yes | H78: L-125-4 | I78: L-861, INSTALL LED MEDIUM INTENSITY RUNWAY EDGE LIGHTS (WHITE/WHITE, 6-UNITS) AND (YELLOW/WHITE, 39-UNITS), BASE MOUNTED ON CONCRETE-ENCASED CAN | J78: EA | K78: 45 | L78: 2600 | M78: 117000 | N78: Yes
A79: NTB2521ZAPAT00053 | B79: Zapata County Airport | C79: 2521ZAPAT | D79: 46309.542 | E79: Anderson Columbia Company, Inc. | F79: 1 | G79: Yes | H79: L-125-5 | I79: INSTALL LED MEDIUM INTENSITY RUNWAY THRESHOLD LIGHTS (RED/RED, 16- UNITS), (BLANK/GREEN, 12-UNITS), AND EDGE LIGHTS (YELLOW/GREEN, 4-UNITS) BASED MOUNTED ON CONCRETE-ENCASED CAN, AS SPECIFIED ON PLANS | J79: EA | K79: 32 | L79: 2600 | M79: 83200 | N79: Yes
A80: NTB2521ZAPAT00053 | B80: Zapata County Airport | C80: 2521ZAPAT | D80: 46309.542 | E80: Anderson Columbia Company, Inc. | F80: 1 | G80: Yes | H80: L-125-6 | I80: ONE MODULE, SIZE 1, STYLE 2, INTERNALLY LIGHTED LED GUIDANCE SIGN, BASE MOUNTED ON CONCRETE-ENCASED CAN | J80: EA | K80: 10 | L80: 7000 | M80: 70000 | N80: Yes
A81: NTB2521ZAPAT00053 | B81: Zapata County Airport | C81: 2521ZAPAT | D81: 46309.542 | E81: Anderson Columbia Company, Inc. | F81: 1 | G81: Yes | H81: L-125-8 | I81: THREE MODULE, SIZE 1, STYLE 2, INTERNALLY LIGHTED LED GUIDANCE SIGN, BASE MOUNTED ON CONCRETE-ENCASED CAN | J81: EA | K81: 1 | L81: 11000 | M81: 11000 | N81: Yes
A82: NTB2521ZAPAT00053 | B82: Zapata County Airport | C82: 2521ZAPAT | D82: 46309.542 | E82: Anderson Columbia Company, Inc. | F82: 1 | G82: Yes | H82: L-125-9 | I82: INSTALL NEW L-881, PAPI-2, STYLE B, LED TILUMINATION, EQUIPPED WITH INTERNAL ADJUSTABLE BAFFLES, MOUNTED ON CONCRETE FOUNDATIONS, COMPLETE, INCLUDING ADJUSTMENTS DURING FAA FLIGHT INSPECTION | J82: EA | K82: 2 | L82: 28000 | M82: 56000 | N82: Yes
A83: NTB2521ZAPAT00053 | B83: Zapata County Airport | C83: 2521ZAPAT | D83: 46309.542 | E83: Anderson Columbia Company, Inc. | F83: 1 | G83: Yes | H83: L-125-10 | I83: INSTALL L-853 TAXIWAY REFLECTIVE MARKERS (BLUE 86-UNITS AND GREEN 53-UNITS) AS SPECIFIED ON PLANS, COMPLETE IN PLACE | J83: EA | K83: 139 | L83: 20 | M83: 2780 | N83: Yes
A84: NTB2521ZAPAT00053 | B84: Zapata County Airport | C84: 2521ZAPAT | D84: 46309.542 | E84: Anderson Columbia Company, Inc. | F84: 1 | G84: Yes | H84: P-610-6.2 | I84: PREPARE, INSTALL 100- X 10- FOOT THRESHOLD CONCRETE PAD AROUND L-806 LIGHT BASES, COMPLETE IN PLACE | J84: EA | K84: 2 | L84: 31500 | M84: 63000 | N84: Yes
A85: NTB2521ZAPAT00053 | B85: Zapata County Airport | C85: 2521ZAPAT | D85: 46309.542 | E85: Anderson Columbia Company, Inc. | F85: 1 | G85: Yes | H85: P-610-6.3 | I85: PREPARE, INSTALL 40- X 10-FOOT DISPLACED THRESHOLD CONCRETE PAD AROUND L-806 LIGHT BASES, COMPLETE IN PLACE | J85: EA | K85: 4 | L85: 13500 | M85: 54000 | N85: Yes
A86: NTB2521ZAPAT00053 | B86: Zapata County Airport | C86: 2521ZAPAT | D86: 46309.542 | E86: Sterling Delaware Holding Company | F86: 2 | G86: No | H86: C-105 | I86: CONTRACTOR MOBILIZATION (8%) | J86: LS | K86: 1 | L86: 500000 | M86: 500000 | N86: Yes
A87: NTB2521ZAPAT00053 | B87: Zapata County Airport | C87: 2521ZAPAT | D87: 46309.542 | E87: Sterling Delaware Holding Company | F87: 2 | G87: No | H87: C-100 | I87: CONTRACTOR QUALITY CONTROL PROGRAM | J87: LS | K87: 1 | L87: 150000 | M87: 150000 | N87: Yes
... A125: NTB2521ZAPAT00053 | B125: Zapata County Airport | C125: 2521ZAPAT | D125: 46309.542 | E125: Sterling Delaware Holding Company | F125: 2 | G125: No | H125: L-115.2 | I125: HEAVY-DUTY ELECTRICAL BOX WITH LID, 17X30X24 INCHES, AT VAULT BUILDING | J125: EA | K125: 3 | L125: 3003.35 | M125: 9010.05 | N125: Yes
A126: NTB2521ZAPAT00053 | B126: Zapata County Airport | C126: 2521ZAPAT | D126: 46309.542 | E126: Sterling Delaware Holding Company | F126: 2 | G126: No | H126: L-125.1 | I126: REMOVE AND DISPOSE OFF SITE, EXISTING STAKE-MOUNTED RUNWAY EDGE ‘LIGHTS FIXTURES (INCLUDING ALL UNDERGROUND ‘CONDUIT, WIRING CONNECTIONS, AND BOXES), MIRLS | K126: 118 | L126: 200.22 | M126: 23625.96 | N126: Yes
A127: NTB2521ZAPAT00053 | B127: Zapata County Airport | C127: 2521ZAPAT | D127: 46309.542 | E127: Sterling Delaware Holding Company | F127: 2 | G127: No | H127: L-125.2 | I127: REMOVE AND DISPOSE OFF SITE, EXISTING DIRECTIONAL SIGNAGE {INCLUDING ALL UNDERGROUND CONDUIT, WIRING CONNECTIONS, BOXES, AND CONCRETE PADS) | J127: EA | K127: 11 | L127: 500.56 | M127: 5506.16 | N127: Yes
A128: NTB2521ZAPAT00053 | B128: Zapata County Airport | C128: 2521ZAPAT | D128: 46309.542 | E128: Sterling Delaware Holding Company | F128: 2 | G128: No | H128: L-125-3 | I128: REMOVE AND DISPOSE OFF SITE, EXISTING REILS UNITS ON RWY 12-30 END {INCLUDING ALL UNDERGROUND CONDUIT, WIRING CONNECTIONS, BOXES, AND CONCRETE FOUNDATION PADS) | J128: EA | K128: 4 | L128: 1001.12 | M128: 4004.48 | N128: Yes
A129: NTB2521ZAPAT00053 | B129: Zapata County Airport | C129: 2521ZAPAT | D129: 46309.542 | E129: Sterling Delaware Holding Company | F129: 2 | G129: No | H129: L-125-4 | I129: L-861, INSTALL LED MEDIUM INTENSITY RUNWAY EDGE LIGHTS (WHITE/WHITE, 6-UNITS) AND (YELLOW/WHITE, 39-UNITS), BASE MOUNTED ON CONCRETE-ENCASED CAN | J129: EA | K129: 45 | L129: 1501.68 | M129: 67575.6 | N129: Yes
A130: NTB2521ZAPAT00053 | B130: Zapata County Airport | C130: 2521ZAPAT | D130: 46309.542 | E130: Sterling Delaware Holding Company | F130: 2 | G130: No | H130: L-125-5 | I130: INSTALL LED MEDIUM INTENSITY RUNWAY THRESHOLD LIGHTS (RED/RED, 16- UNITS), (BLANK/GREEN, 12-UNITS), AND EDGE LIGHTS (YELLOW/GREEN, 4-UNITS) BASED MOUNTED ON CONCRETE-ENCASED CAN, AS SPECIFIED ON PLANS | J130: EA | K130: 32 | L130: 1802.01 | M130: 57664.32 | N130: Yes
A131: NTB2521ZAPAT00053 | B131: Zapata County Airport | C131: 2521ZAPAT | D131: 46309.542 | E131: Sterling Delaware Holding Company | F131: 2 | G131: No | H131: L-125-6 | I131: ONE MODULE, SIZE 1, STYLE 2, INTERNALLY LIGHTED LED GUIDANCE SIGN, BASE MOUNTED ON CONCRETE-ENCASED CAN | J131: EA | K131: 10 | L131: 4505.03 | M131: 45050.3 | N131: Yes
A132: NTB2521ZAPAT00053 | B132: Zapata County Airport | C132: 2521ZAPAT | D132: 46309.542 | E132: Sterling Delaware Holding Company | F132: 2 | G132: No | H132: L-125-8 | I132: THREE MODULE, SIZE 1, STYLE 2, INTERNALLY LIGHTED LED GUIDANCE SIGN, BASE MOUNTED ON CONCRETE-ENCASED CAN | J132: EA | K132: 1 | L132: 6006.7 | M132: 6006.7 | N132: Yes
A133: NTB2521ZAPAT00053 | B133: Zapata County Airport | C133: 2521ZAPAT | D133: 46309.542 | E133: Sterling Delaware Holding Company | F133: 2 | G133: No | H133: L-125-9 | I133: INSTALL NEW L-881, PAPI-2, STYLE B, LED TILUMINATION, EQUIPPED WITH INTERNAL ADJUSTABLE BAFFLES, MOUNTED ON CONCRETE FOUNDATIONS, COMPLETE, INCLUDING ADJUSTMENTS DURING FAA FLIGHT INSPECTION | J133: EA | K133: 2 | L133: 35039.1 | M133: 70078.2 | N133: Yes
A134: NTB2521ZAPAT00053 | B134: Zapata County Airport | C134: 2521ZAPAT | D134: 46309.542 | E134: Sterling Delaware Holding Company | F134: 2 | G134: No | H134: L-125-10 | I134: INSTALL L-853 TAXIWAY REFLECTIVE MARKERS (BLUE 86-UNITS AND GREEN 53-UNITS) AS SPECIFIED ON PLANS, COMPLETE IN PLACE | J134: EA | K134: 139 | L134: 19 | M134: 2641 | N134: Yes
A135: NTB2521ZAPAT00053 | B135: Zapata County Airport | C135: 2521ZAPAT | D135: 46309.542 | E135: Sterling Delaware Holding Company | F135: 2 | G135: No | H135: P-610-6.2 | I135: PREPARE, INSTALL 100- X 10- FOOT THRESHOLD CONCRETE PAD AROUND L-806 LIGHT BASES, COMPLETE IN PLACE | J135: EA | K135: 2 | L135: 20022.35 | M135: 40044.7 | N135: Yes
A136: NTB2521ZAPAT00053 | B136: Zapata County Airport | C136: 2521ZAPAT | D136: 46309.542 | E136: Sterling Delaware Holding Company | F136: 2 | G136: No | H136: P-610-6.3 | I136: PREPARE, INSTALL 40- X 10-FOOT DISPLACED THRESHOLD CONCRETE PAD AROUND L-806 LIGHT BASES, COMPLETE IN PLACE | J136: EA | K136: 4 | L136: 8008.94 | M136: 32035.76 | N136: Yes
